Workbook
Name _gjdgxs: data!#REF!

Sheet data
A1: HỆ THỐNG QUẢN LÝ HỌC SINH TRƯỜNG THPT VỊ THANH
C2: Tiêu đề: | K2: Giờ bắt đầu | L2: 0.29166667 | M2: Giờ kết thúc | Q2: 0.5625
A3: TT | B3: HỌ VÀ TÊN | C3: LỚP | D3: ID xa | E3: MÃ HS | N3: =N2-P2 -> 0 | P3: VẮNG | R3: Thẻ lỗi, liên hệ Admin
F4: CÓ MẶT | G4: LỚP | H4: ID PHHS | I4: KIỂM TRA TÊN HS | J4: CHECK IN | K4: THỜI GIAN | L4: VÔ TRỄ | M4: THỜI GIAN TRỄ | N4: Buổi | O4: VỀ SỚM KHÔNG BÁO | P4: P | Q4: K | S4: NK | T4: NK1 | U4: ngày sinh | V4: ngày sinh1 | X4: điểm TB | Y4: MÃ MỚI CẤP LẠI
A5: =IF(B5<>"",A4+1,"") -> 1 | B5: TRẦN VIẾT BÌNH AN | C5: 10A1 | D5: 33000000 | E5: 20234379 | F5: =IFERROR(IF(VLOOKUP(E5,J:J,1,0)=E5,"X",""),"") | G5: =IF(J5<>"", INDEX($C$5:$C$1433, MATCH(J5, $E$5:$E$1433, 0)),"") -> #N/A | H5: =IF(J5<>"", INDEX($D$5:$D$1433, MATCH(J5, $E$5:$E$1433, 0)),"") -> #N/A | I5: =IFERROR(IF(J5<>"", INDEX($B$5:$B$1433, MATCH(J5, $E$5:$E$1433, 0)),""),"SAI") -> SAI | J5: 320006190 | K5: 1:12:05 PM | L5: =IFERROR(IF($N$5="Sáng",IF(MID(K5,2,7)-MID($L$2,2,7)>0,"Trễ",""),IF(MID(K5,2,7)-MID($Q$2,2,7)>0,"Trễ","")),"") | M5: =IFERROR(IF($N$5="Sáng",MID(K5,2,7)-MID($L$2,2,7),MID(K5,2,7)-MID($Q$2,2,7)),"") -> -0.24160813 | N5: sáng | Q5: =IF(B5<>"",IF(AND(P5="",F5=""),"Không phép ",""),"") -> Không phép | R5: =UPPER(B5) -> TRẦN VIẾT BÌNH AN | S5: 2026-2029 | T5: =IFERROR(IF(J5<>"", INDEX($S$5:$S$1433, MATCH(J5, $E$5:$E$1433, 0)),""),"") | U5: 07/3/2011 | V5: =IFERROR(IF(J5<>"", INDEX($U$5:$U$1433, MATCH(J5, $E$5:$E$1433, 0)),""),"") | Y5: 330000000 | Z5: =LEFT(Y5,8) -> 33000000 | AA5: AN
A6: =IF(B6<>"",A5+1,"") -> 2 | B6: NGUYỄN THỊ MAI ANH | C6: 10A1 | D6: 33000001 | E6: 19104651 | F6: =IFERROR(IF(VLOOKUP(E6,J:J,1,0)=E6,"X",""),"") | G6: =IF(J6<>"", INDEX($C$5:$C$1433, MATCH(J6, $E$5:$E$1433, 0)),"") -> 11A6 | H6: =IF(J6<>"", INDEX($D$5:$D$1433, MATCH(J6, $E$5:$E$1433, 0)),"") -> 0 | I6: =IFERROR(IF(J6<>"", INDEX($B$5:$B$1433, MATCH(J6, $E$5:$E$1433, 0)),""),"SAI") -> VÕ ĐÌNH THIÊN | J6: 32000764 | K6: 5:58:09 AM | L6: =IFERROR(IF($N$5="Sáng",IF(MID(K6,2,7)-MID($L$2,2,7)>0,"Trễ",""),IF(MID(K6,2,7)-MID($Q$2,2,7)>0,"Trễ","")),"") | M6: =IFERROR(IF($N$5="Sáng",MID(K6,2,7)-MID($L$2,2,7),MID(K6,2,7)-MID($Q$2,2,7)),"") -> -0.042950722 | Q6: =IF(B6<>"",IF(AND(P6="",F6=""),"Không phép ",""),"") -> Không phép | R6: =UPPER(B6) -> NGUYỄN THỊ MAI ANH | S6: 2026-2029 | T6: =IFERROR(IF(J6<>"", INDEX($S$5:$S$1433, MATCH(J6, $E$5:$E$1433, 0)),""),"") -> 2025-2028 | U6: 28/3/2011 | V6: =IFERROR(IF(J6<>"", INDEX($U$5:$U$1433, MATCH(J6, $E$5:$E$1433, 0)),""),"") -> 40454 | Y6: =Y5+10 -> 330000010 | Z6: =LEFT(Y6,8) -> 33000001 | AA6: ANH
A7: =IF(B7<>"",A6+1,"") -> 3 | B7: TRẦN HUỲNH KHÁNH BĂNG | C7: 10A1 | D7: 33000002 | E7: 19442443 | F7: =IFERROR(IF(VLOOKUP(E7,J:J,1,0)=E7,"X",""),"") | G7: =IF(J7<>"", INDEX($C$5:$C$1433, MATCH(J7, $E$5:$E$1433, 0)),"") -> 12A10 | H7: =IF(J7<>"", INDEX($D$5:$D$1433, MATCH(J7, $E$5:$E$1433, 0)),"") -> 0 | I7: =IFERROR(IF(J7<>"", INDEX($B$5:$B$1433, MATCH(J7, $E$5:$E$1433, 0)),""),"SAI") -> TRẦN PHAN MINH ĐĂNG | J7: 32000409 | K7: 6:00:55 AM | L7: =IFERROR(IF($N$5="Sáng",IF(MID(K7,2,7)-MID($L$2,2,7)>0,"Trễ",""),IF(MID(K7,2,7)-MID($Q$2,2,7)>0,"Trễ","")),"") | M7: =IFERROR(IF($N$5="Sáng",MID(K7,2,7)-MID($L$2,2,7),MID(K7,2,7)-MID($Q$2,2,7)),"") -> -0.041029426 | Q7: =IF(B7<>"",IF(AND(P7="",F7=""),"Không phép ",""),"") -> Không phép | R7: =UPPER(B7) -> TRẦN HUỲNH KHÁNH BĂNG | S7: 2026-2029 | T7: =IFERROR(IF(J7<>"", INDEX($S$5:$S$1433, MATCH(J7, $E$5:$E$1433, 0)),""),"") -> 2024-2027 | U7: 30/3/2011 | V7: =IFERROR(IF(J7<>"", INDEX($U$5:$U$1433, MATCH(J7, $E$5:$E$1433, 0)),""),"") -> 39973 | Y7: =Y6+10 -> 330000020 | Z7: =LEFT(Y7,8) -> 33000002 | AA7: BĂNG
A8: =IF(B8<>"",A7+1,"") -> 4 | B8: TRẦN NGUYỄN THẾ BẢO | C8: 10A1 | D8: 33000003 | E8: 3848235 | F8: =IFERROR(IF(VLOOKUP(E8,J:J,1,0)=E8,"X",""),"") | G8: =IF(J8<>"", INDEX($C$5:$C$1433, MATCH(J8, $E$5:$E$1433, 0)),"") -> 12A10 | H8: =IF(J8<>"", INDEX($D$5:$D$1433, MATCH(J8, $E$5:$E$1433, 0)),"") -> 0 | I8: =IFERROR(IF(J8<>"", INDEX($B$5:$B$1433, MATCH(J8, $E$5:$E$1433, 0)),""),"SAI") -> HUỲNH TẤN LỘC | J8: 32000418 | K8: 6:04:58 AM | L8: =IFERROR(IF($N$5="Sáng",IF(MID(K8,2,7)-MID($L$2,2,7)>0,"Trễ",""),IF(MID(K8,2,7)-MID($Q$2,2,7)>0,"Trễ","")),"") | M8: =IFERROR(IF($N$5="Sáng",MID(K8,2,7)-MID($L$2,2,7),MID(K8,2,7)-MID($Q$2,2,7)),"") -> -0.038216926 | Q8: =IF(B8<>"",IF(AND(P8="",F8=""),"Không phép ",""),"") -> Không phép | R8: =UPPER(B8) -> TRẦN NGUYỄN THẾ BẢO | S8: 2026-2029 | T8: =IFERROR(IF(J8<>"", INDEX($S$5:$S$1433, MATCH(J8, $E$5:$E$1433, 0)),""),"") -> 2024-2027 | U8: 24/7/2011 | V8: =IFERROR(IF(J8<>"", INDEX($U$5:$U$1433, MATCH(J8, $E$5:$E$1433, 0)),""),"") -> 29/09/2009 | Y8: =Y7+10 -> 330000030 | Z8: =LEFT(Y8,8) -> 33000003 | AA8: BẢO
A9: =IF(B9<>"",A8+1,"") -> 5 | B9: THÁI AN BÌNH | C9: 10A1 | D9: 33000004 | E9: 19510171 | F9: =IFERROR(IF(VLOOKUP(E9,J:J,1,0)=E9,"X",""),"") | G9: =IF(J9<>"", INDEX($C$5:$C$1433, MATCH(J9, $E$5:$E$1433, 0)),"") -> 12A9 | H9: =IF(J9<>"", INDEX($D$5:$D$1433, MATCH(J9, $E$5:$E$1433, 0)),"") -> 0 | I9: =IFERROR(IF(J9<>"", INDEX($B$5:$B$1433, MATCH(J9, $E$5:$E$1433, 0)),""),"SAI") -> TRẦN BẢO NGỌC | J9: 32000377 | K9: 6:06:51 AM | L9: =IFERROR(IF($N$5="Sáng",IF(MID(K9,2,7)-MID($L$2,2,7)>0,"Trễ",""),IF(MID(K9,2,7)-MID($Q$2,2,7)>0,"Trễ","")),"") | M9: =IFERROR(IF($N$5="Sáng",MID(K9,2,7)-MID($L$2,2,7),MID(K9,2,7)-MID($Q$2,2,7)),"") -> -0.036909056 | Q9: =IF(B9<>"",IF(AND(P9="",F9=""),"Không phép ",""),"") -> Không phép | R9: =UPPER(B9) -> THÁI AN BÌNH | S9: 2026-2029 | T9: =IFERROR(IF(J9<>"", INDEX($S$5:$S$1433, MATCH(J9, $E$5:$E$1433, 0)),""),"") -> 2024-2027 | U9: 18/4/2011 | V9: =IFERROR(IF(J9<>"", INDEX($U$5:$U$1433, MATCH(J9, $E$5:$E$1433, 0)),""),"") -> 40062 | Y9: =Y8+10 -> 330000040 | Z9: =LEFT(Y9,8) -> 33000004 | AA9: BÌNH
A10: =IF(B10<>"",A9+1,"") -> 6 | B10: TRẦN VŨ NAM BÌNH | C10: 10A1 | D10: 33000005 | E10: 12017163 | F10: =IFERROR(IF(VLOOKUP(E10,J:J,1,0)=E10,"X",""),"") | G10: =IF(J10<>"", INDEX($C$5:$C$1433, MATCH(J10, $E$5:$E$1433, 0)),"") -> 11A5 | H10: =IF(J10<>"", INDEX($D$5:$D$1433, MATCH(J10, $E$5:$E$1433, 0)),"") -> 0 | I10: =IFERROR(IF(J10<>"", INDEX($B$5:$B$1433, MATCH(J10, $E$5:$E$1433, 0)),""),"SAI") -> BÙI VĂN PHÚ | J10: 32000722 | K10: 6:09:25 AM | L10: =IFERROR(IF($N$5="Sáng",IF(MID(K10,2,7)-MID($L$2,2,7)>0,"Trễ",""),IF(MID(K10,2,7)-MID($Q$2,2,7)>0,"Trễ","")),"") | M10: =IFERROR(IF($N$5="Sáng",MID(K10,2,7)-MID($L$2,2,7),MID(K10,2,7)-MID($Q$2,2,7)),"") -> -0.035126648 | Q10: =IF(B10<>"",IF(AND(P10="",F10=""),"Không phép ",""),"") -> Không phép | R10: =UPPER(B10) -> TRẦN VŨ NAM BÌNH | S10: 2026-2029 | T10: =IFERROR(IF(J10<>"", INDEX($S$5:$S$1433, MATCH(J10, $E$5:$E$1433, 0)),""),"") -> 2025-2028 | U10: 24/10/2011 | V10: =IFERROR(IF(J10<>"", INDEX($U$5:$U$1433, MATCH(J10, $E$5:$E$1433, 0)),""),"") -> 40243 | Y10: =Y9+10 -> 330000050 | Z10: =LEFT(Y10,8) -> 33000005 | AA10: BÌNH
A11: =IF(B11<>"",A10+1,"") -> 7 | B11: LÝ NGUYỄN KHÁNH DI | C11: 10A1 | D11: 33000006 | E11: 19725675 | F11: =IFERROR(IF(VLOOKUP(E11,J:J,1,0)=E11,"X",""),"") | G11: =IF(J11<>"", INDEX($C$5:$C$1433, MATCH(J11, $E$5:$E$1433, 0)),"") -> 11A5 | H11: =IF(J11<>"", INDEX($D$5:$D$1433, MATCH(J11, $E$5:$E$1433, 0)),"") -> 0 | I11: =IFERROR(IF(J11<>"", INDEX($B$5:$B$1433, MATCH(J11, $E$5:$E$1433, 0)),""),"SAI") -> BÙI VĂN PHÚ | J11: 32000722 | K11: 6:09:25 AM | L11: =IFERROR(IF($N$5="Sáng",IF(MID(K11,2,7)-MID($L$2,2,7)>0,"Trễ",""),IF(MID(K11,2,7)-MID($Q$2,2,7)>0,"Trễ","")),"") | M11: =IFERROR(IF($N$5="Sáng",MID(K11,2,7)-MID($L$2,2,7),MID(K11,2,7)-MID($Q$2,2,7)),"") -> -0.035126648 | Q11: =IF(B11<>"",IF(AND(P11="",F11=""),"Không phép ",""),"") -> Không phép | R11: =UPPER(B11) -> LÝ NGUYỄN KHÁNH DI | S11: 2026-2029 | T11: =IFERROR(IF(J11<>"", INDEX($S$5:$S$1433, MATCH(J11, $E$5:$E$1433, 0)),""),"") -> 2025-2028 | U11: 09/11/2011 | V11: =IFERROR(IF(J11<>"", INDEX($U$5:$U$1433, MATCH(J11, $E$5:$E$1433, 0)),""),"") -> 40243 | Y11: =Y10+10 -> 330000060 | Z11: =LEFT(Y11,8) -> 33000006 | AA11: DI
A12: =IF(B12<>"",A11+1,"") -> 8 | B12: LÊ NGUYỄN HUYỀN DIỆU | C12: 10A1 | D12: 33000007 | E12: 19710139 | F12: =IFERROR(IF(VLOOKUP(E12,J:J,1,0)=E12,"X",""),"") | G12: =IF(J12<>"", INDEX($C$5:$C$1433, MATCH(J12, $E$5:$E$1433, 0)),"") -> 11A7 | H12: =IF(J12<>"", INDEX($D$5:$D$1433, MATCH(J12, $E$5:$E$1433, 0)),"") -> 0 | I12: =IFERROR(IF(J12<>"", INDEX($B$5:$B$1433, MATCH(J12, $E$5:$E$1433, 0)),""),"SAI") -> ĐẶNG MINH TRÍ | J12: 32000816 | K12: 6:12:52 AM | L12: =IFERROR(IF($N$5="Sáng",IF(MID(K12,2,7)-MID($L$2,2,7)>0,"Trễ",""),IF(MID(K12,2,7)-MID($Q$2,2,7)>0,"Trễ","")),"") | M12: =IFERROR(IF($N$5="Sáng",MID(K12,2,7)-MID($L$2,2,7),MID(K12,2,7)-MID($Q$2,2,7)),"") -> -0.032730815 | Q12: =IF(B12<>"",IF(AND(P12="",F12=""),"Không phép ",""),"") -> Không phép | R12: =UPPER(B12) -> LÊ NGUYỄN HUYỀN DIỆU | S12: 2026-2029 | T12: =IFERROR(IF(J12<>"", INDEX($S$5:$S$1433, MATCH(J12, $E$5:$E$1433, 0)),""),"") -> 2025-2028 | U12: 14/11/2011 | V12: =IFERROR(IF(J12<>"", INDEX($U$5:$U$1433, MATCH(J12, $E$5:$E$1433, 0)),""),"") -> 29/7/2010 | Y12: =Y11+10 -> 330000070 | Z12: =LEFT(Y12,8) -> 33000007 | AA12: DIỆU
A13: =IF(B13<>"",A12+1,"") -> 9 | B13: HỨA THANH DUNG | C13: 10A1 | D13: 33000008 | E13: 20229003 | F13: =IFERROR(IF(VLOOKUP(E13,J:J,1,0)=E13,"X",""),"") | G13: =IF(J13<>"", INDEX($C$5:$C$1433, MATCH(J13, $E$5:$E$1433, 0)),"") -> 11A9 | H13: =IF(J13<>"", INDEX($D$5:$D$1433, MATCH(J13, $E$5:$E$1433, 0)),"") -> 0 | I13: =IFERROR(IF(J13<>"", INDEX($B$5:$B$1433, MATCH(J13, $E$5:$E$1433, 0)),""),"SAI") -> LÊ NGUYỄN THIÊN PHƯỚC | J13: 32000891 | K13: 6:13:44 AM | L13: =IFERROR(IF($N$5="Sáng",IF(MID(K13,2,7)-MID($L$2,2,7)>0,"Trễ",""),IF(MID(K13,2,7)-MID($Q$2,2,7)>0,"Trễ","")),"") | M13: =IFERROR(IF($N$5="Sáng",MID(K13,2,7)-MID($L$2,2,7),MID(K13,2,7)-MID($Q$2,2,7)),"") -> -0.032128963 | Q13: =IF(B13<>"",IF(AND(P13="",F13=""),"Không phép ",""),"") -> Không phép | R13: =UPPER(B13) -> HỨA THANH DUNG | S13: 2026-2029 | T13: =IFERROR(IF(J13<>"", INDEX($S$5:$S$1433, MATCH(J13, $E$5:$E$1433, 0)),""),"") -> 2025-2028 | U13: 18/9/2011 | V13: =IFERROR(IF(J13<>"", INDEX($U$5:$U$1433, MATCH(J13, $E$5:$E$1433, 0)),""),"") -> 23/6/2010 | Y13: =Y12+10 -> 330000080 | Z13: =LEFT(Y13,8) -> 33000008 | AA13: DUNG
A14: =IF(B14<>"",A13+1,"") -> 10 | B14: PHAN NGUYỄN THÙY DƯƠNG | C14: 10A1 | D14: 33000009 | E14: 18513067 | F14: =IFERROR(IF(VLOOKUP(E14,J:J,1,0)=E14,"X",""),"") | G14: =IF(J14<>"", INDEX($C$5:$C$1433, MATCH(J14, $E$5:$E$1433, 0)),"") -> 12A7 | H14: =IF(J14<>"", INDEX($D$5:$D$1433, MATCH(J14, $E$5:$E$1433, 0)),"") -> 0 | I14: =IFERROR(IF(J14<>"", INDEX($B$5:$B$1433, MATCH(J14, $E$5:$E$1433, 0)),""),"SAI") -> Nguyễn Viết Tâm | J14: 32000478 | K14: 6:14:02 AM | L14: =IFERROR(IF($N$5="Sáng",IF(MID(K14,2,7)-MID($L$2,2,7)>0,"Trễ",""),IF(MID(K14,2,7)-MID($Q$2,2,7)>0,"Trễ","")),"") | M14: =IFERROR(IF($N$5="Sáng",MID(K14,2,7)-MID($L$2,2,7),MID(K14,2,7)-MID($Q$2,2,7)),"") -> -0.03192063 | Q14: =IF(B14<>"",IF(AND(P14="",F14=""),"Không phép ",""),"") -> Không phép | R14: =UPPER(B14) -> PHAN NGUYỄN THÙY DƯƠNG | S14: 2026-2029 | T14: =IFERROR(IF(J14<>"", INDEX($S$5:$S$1433, MATCH(J14, $E$5:$E$1433, 0)),""),"") -> 2024-2027 | U14: 29/10/2011 | V14: =IFERROR(IF(J14<>"", INDEX($U$5:$U$1433, MATCH(J14, $E$5:$E$1433, 0)),""),"") -> 19/10/2009 | Y14: =Y13+10 -> 330000090 | Z14: =LEFT(Y14,8) -> 33000009 | AA14: DƯƠNG
A15: =IF(B15<>"",A14+1,"") -> 11 | B15: THÁI LÝ GIA HÂN | C15: 10A1 | D15: 33000010 | E15: 19811195 | F15: =IFERROR(IF(VLOOKUP(E15,J:J,1,0)=E15,"X",""),"") | G15: =IF(J15<>"", INDEX($C$5:$C$1433, MATCH(J15, $E$5:$E$1433, 0)),"") -> 12A2 | H15: =IF(J15<>"", INDEX($D$5:$D$1433, MATCH(J15, $E$5:$E$1433, 0)),"") -> 0 | I15: =IFERROR(IF(J15<>"", INDEX($B$5:$B$1433, MATCH(J15, $E$5:$E$1433, 0)),""),"SAI") -> TRẦN KỲ ANH | J15: 32000048 | K15: 6:16:48 AM | L15: =IFERROR(IF($N$5="Sáng",IF(MID(K15,2,7)-MID($L$2,2,7)>0,"Trễ",""),IF(MID(K15,2,7)-MID($Q$2,2,7)>0,"Trễ","")),"") | M15: =IFERROR(IF($N$5="Sáng",MID(K15,2,7)-MID($L$2,2,7),MID(K15,2,7)-MID($Q$2,2,7)),"") -> -0.029999333 | Q15: =IF(B15<>"",IF(AND(P15="",F15=""),"Không phép ",""),"") -> Không phép | R15: =UPPER(B15) -> THÁI LÝ GIA HÂN | S15: 2026-2029 | T15: =IFERROR(IF(J15<>"", INDEX($S$5:$S$1433, MATCH(J15, $E$5:$E$1433, 0)),""),"") -> 2024-2027 | U15: 26/12/2011 | V15: =IFERROR(IF(J15<>"", INDEX($U$5:$U$1433, MATCH(J15, $E$5:$E$1433, 0)),""),"") -> 22/12/2009 | Y15: =Y14+10 -> 330000100 | Z15: =LEFT(Y15,8) -> 33000010 | AA15: HÂN
A16: =IF(B16<>"",A15+1,"") -> 12 | B16: NGUYỄN THỊ PHƯƠNG HẬU | C16: 10A1 | D16: 33000011 | E16: 17409835 | F16: =IFERROR(IF(VLOOKUP(E16,J:J,1,0)=E16,"X",""),"") | G16: =IF(J16<>"", INDEX($C$5:$C$1433, MATCH(J16, $E$5:$E$1433, 0)),"") -> 12A2 | H16: =IF(J16<>"", INDEX($D$5:$D$1433, MATCH(J16, $E$5:$E$1433, 0)),"") -> 0 | I16: =IFERROR(IF(J16<>"", INDEX($B$5:$B$1433, MATCH(J16, $E$5:$E$1433, 0)),""),"SAI") -> TRẦN KỲ ANH | J16: 32000048 | K16: 6:16:49 AM | L16: =IFERROR(IF($N$5="Sáng",IF(MID(K16,2,7)-MID($L$2,2,7)>0,"Trễ",""),IF(MID(K16,2,7)-MID($Q$2,2,7)>0,"Trễ","")),"") | M16: =IFERROR(IF($N$5="Sáng",MID(K16,2,7)-MID($L$2,2,7),MID(K16,2,7)-MID($Q$2,2,7)),"") -> -0.029987759 | Q16: =IF(B16<>"",IF(AND(P16="",F16=""),"Không phép ",""),"") -> Không phép | R16: =UPPER(B16) -> NGUYỄN THỊ PHƯƠNG HẬU | S16: 2026-2029 | T16: =IFERROR(IF(J16<>"", INDEX($S$5:$S$1433, MATCH(J16, $E$5:$E$1433, 0)),""),"") -> 2024-2027 | U16: 23/11/2011 | V16: =IFERROR(IF(J16<>"", INDEX($U$5:$U$1433, MATCH(J16, $E$5:$E$1433, 0)),""),"") -> 22/12/2009 | Y16: =Y15+10 -> 330000110 | Z16: =LEFT(Y16,8) -> 33000011 | AA16: HẬU
A17: =IF(B17<>"",A16+1,"") -> 13 | B17: TRẦN VĨ HIỆP | C17: 10A1 | D17: 33000012 | E17: 19813003 | F17: =IFERROR(IF(VLOOKUP(E17,J:J,1,0)=E17,"X",""),"") | G17: =IF(J17<>"", INDEX($C$5:$C$1433, MATCH(J17, $E$5:$E$1433, 0)),"") -> 12A10 | H17: =IF(J17<>"", INDEX($D$5:$D$1433, MATCH(J17, $E$5:$E$1433, 0)),"") -> 0 | I17: =IFERROR(IF(J17<>"", INDEX($B$5:$B$1433, MATCH(J17, $E$5:$E$1433, 0)),""),"SAI") -> VÕ DUY THÁI | J17: 32000428 | K17: 6:17:37 AM | L17: =IFERROR(IF($N$5="Sáng",IF(MID(K17,2,7)-MID($L$2,2,7)>0,"Trễ",""),IF(MID(K17,2,7)-MID($Q$2,2,7)>0,"Trễ","")),"") | M17: =IFERROR(IF($N$5="Sáng",MID(K17,2,7)-MID($L$2,2,7),MID(K17,2,7)-MID($Q$2,2,7)),"") -> -0.029432204 | Q17: =IF(B17<>"",IF(AND(P17="",F17=""),"Không phép ",""),"") -> Không phép | R17: =UPPER(B17) -> TRẦN VĨ HIỆP | S17: 2026-2029 | T17: =IFERROR(IF(J17<>"", INDEX($S$5:$S$1433, MATCH(J17, $E$5:$E$1433, 0)),""),"") -> 2024-2027 | U17: 04/01/2011 | V17: =IFERROR(IF(J17<>"", INDEX($U$5:$U$1433, MATCH(J17, $E$5:$E$1433, 0)),""),"") -> 25/07/2009 | Y17: =Y16+10 -> 330000120 | Z17: =LEFT(Y17,8) -> 33000012 | AA17: HIỆP
... A37: =IF(B37<>"",A36+1,"") -> 33 | B37: PHẠM THANH TÂM | C37: 10A1 | D37: 33000032 | E37: 20641771 | F37: =IFERROR(IF(VLOOKUP(E37,J:J,1,0)=E37,"X",""),"") | G37: =IF(J37<>"", INDEX($C$5:$C$1433, MATCH(J37, $E$5:$E$1433, 0)),"") -> 12A6 | H37: =IF(J37<>"", INDEX($D$5:$D$1433, MATCH(J37, $E$5:$E$1433, 0)),"") -> 0 | I37: =IFERROR(IF(J37<>"", INDEX($B$5:$B$1433, MATCH(J37, $E$5:$E$1433, 0)),""),"SAI") -> ĐÀO QUỐC HẢI | J37: 32000229 | K37: 6:20:56 AM | L37: =IFERROR(IF($N$5="Sáng",IF(MID(K37,2,7)-MID($L$2,2,7)>0,"Trễ",""),IF(MID(K37,2,7)-MID($Q$2,2,7)>0,"Trễ","")),"") | M37: =IFERROR(IF($N$5="Sáng",MID(K37,2,7)-MID($L$2,2,7),MID(K37,2,7)-MID($Q$2,2,7)),"") -> -0.027128963 | Q37: =IF(B37<>"",IF(AND(P37="",F37=""),"Không phép ",""),"") -> Không phép | R37: =UPPER(B37) -> PHẠM THANH TÂM | S37: 2026-2029 | T37: =IFERROR(IF(J37<>"", INDEX($S$5:$S$1433, MATCH(J37, $E$5:$E$1433, 0)),""),"") -> 2024-2027 | U37: 28/8/2011 | V37: =IFERROR(IF(J37<>"", INDEX($U$5:$U$1433, MATCH(J37, $E$5:$E$1433, 0)),""),"") -> 39879 | Y37: =Y36+10 -> 330000320 | Z37: =LEFT(Y37,8) -> 33000032 | AA37: TÂM
A38: =IF(B38<>"",A37+1,"") -> 34 | B38: CAO THẮNG | C38: 10A1 | D38: 33000033 | E38: 16746955 | F38: =IFERROR(IF(VLOOKUP(E38,J:J,1,0)=E38,"X",""),"") | G38: =IF(J38<>"", INDEX($C$5:$C$1433, MATCH(J38, $E$5:$E$1433, 0)),"") -> 12A7 | H38: =IF(J38<>"", INDEX($D$5:$D$1433, MATCH(J38, $E$5:$E$1433, 0)),"") -> 0 | I38: =IFERROR(IF(J38<>"", INDEX($B$5:$B$1433, MATCH(J38, $E$5:$E$1433, 0)),""),"SAI") -> NGUYỄN GIA PHÚC | J38: 32000289 | K38: 6:21:05 AM | L38: =IFERROR(IF($N$5="Sáng",IF(MID(K38,2,7)-MID($L$2,2,7)>0,"Trễ",""),IF(MID(K38,2,7)-MID($Q$2,2,7)>0,"Trễ","")),"") | M38: =IFERROR(IF($N$5="Sáng",MID(K38,2,7)-MID($L$2,2,7),MID(K38,2,7)-MID($Q$2,2,7)),"") -> -0.027024796 | Q38: =IF(B38<>"",IF(AND(P38="",F38=""),"Không phép ",""),"") -> Không phép | R38: =UPPER(B38) -> CAO THẮNG | S38: 2026-2029 | T38: =IFERROR(IF(J38<>"", INDEX($S$5:$S$1433, MATCH(J38, $E$5:$E$1433, 0)),""),"") -> 2024-2027 | U38: 15/01/2011 | V38: =IFERROR(IF(J38<>"", INDEX($U$5:$U$1433, MATCH(J38, $E$5:$E$1433, 0)),""),"") -> 24/05/2009 | Y38: =Y37+10 -> 330000330 | Z38: =LEFT(Y38,8) -> 33000033 | AA38: THẮNG | AB38: chỉnh lại thẻ 11 (21-1-26)
A39: =IF(B39<>"",A38+1,"") -> 35 | B39: TRIỆU HOÀNG THANH | C39: 10A1 | D39: 33000034 | E39: 20625371 | F39: =IFERROR(IF(VLOOKUP(E39,J:J,1,0)=E39,"X",""),"") | G39: =IF(J39<>"", INDEX($C$5:$C$1433, MATCH(J39, $E$5:$E$1433, 0)),"") -> 11A4 | H39: =IF(J39<>"", INDEX($D$5:$D$1433, MATCH(J39, $E$5:$E$1433, 0)),"") -> 0 | I39: =IFERROR(IF(J39<>"", INDEX($B$5:$B$1433, MATCH(J39, $E$5:$E$1433, 0)),""),"SAI") -> NGUYỄN KHÁNH VÂN | J39: 32000690 | K39: 6:21:20 AM | L39: =IFERROR(IF($N$5="Sáng",IF(MID(K39,2,7)-MID($L$2,2,7)>0,"Trễ",""),IF(MID(K39,2,7)-MID($Q$2,2,7)>0,"Trễ","")),"") | M39: =IFERROR(IF($N$5="Sáng",MID(K39,2,7)-MID($L$2,2,7),MID(K39,2,7)-MID($Q$2,2,7)),"") -> -0.026851185 | Q39: =IF(B39<>"",IF(AND(P39="",F39=""),"Không phép ",""),"") -> Không phép | R39: =UPPER(B39) -> TRIỆU HOÀNG THANH | S39: 2026-2029 | T39: =IFERROR(IF(J39<>"", INDEX($S$5:$S$1433, MATCH(J39, $E$5:$E$1433, 0)),""),"") -> 2025-2028 | U39: 04/12/2011 | V39: =IFERROR(IF(J39<>"", INDEX($U$5:$U$1433, MATCH(J39, $E$5:$E$1433, 0)),""),"") -> 40454 | Y39: =Y38+10 -> 330000340 | Z39: =LEFT(Y39,8) -> 33000034 | AA39: THANH
A40: =IF(B40<>"",A39+1,"") -> 36 | B40: LÊ NGUYỄN ANH THI | C40: 10A1 | D40: 33000035 | E40: 19653915 | F40: =IFERROR(IF(VLOOKUP(E40,J:J,1,0)=E40,"X",""),"") | G40: =IF(J40<>"", INDEX($C$5:$C$1433, MATCH(J40, $E$5:$E$1433, 0)),"") -> 12A6 | H40: =IF(J40<>"", INDEX($D$5:$D$1433, MATCH(J40, $E$5:$E$1433, 0)),"") -> 0 | I40: =IFERROR(IF(J40<>"", INDEX($B$5:$B$1433, MATCH(J40, $E$5:$E$1433, 0)),""),"SAI") -> BÙI KIM BẢO NGỌC | J40: 32000239 | K40: 6:21:31 AM | L40: =IFERROR(IF($N$5="Sáng",IF(MID(K40,2,7)-MID($L$2,2,7)>0,"Trễ",""),IF(MID(K40,2,7)-MID($Q$2,2,7)>0,"Trễ","")),"") | M40: =IFERROR(IF($N$5="Sáng",MID(K40,2,7)-MID($L$2,2,7),MID(K40,2,7)-MID($Q$2,2,7)),"") -> -0.02672387 | Q40: =IF(B40<>"",IF(AND(P40="",F40=""),"Không phép ",""),"") -> Không phép | R40: =UPPER(B40) -> LÊ NGUYỄN ANH THI | S40: 2026-2029 | T40: =IFERROR(IF(J40<>"", INDEX($S$5:$S$1433, MATCH(J40, $E$5:$E$1433, 0)),""),"") -> 2024-2027 | U40: 14/8/2011 | V40: =IFERROR(IF(J40<>"", INDEX($U$5:$U$1433, MATCH(J40, $E$5:$E$1433, 0)),""),"") -> 40030 | Y40: =Y39+10 -> 330000350 | Z40: =LEFT(Y40,8) -> 33000035 | AA40: THI
A41: =IF(B41<>"",A40+1,"") -> 37 | B41: NGUYỄN LÊ GIA THỊNH | C41: 10A1 | D41: 33000036 | E41: 19111707 | F41: =IFERROR(IF(VLOOKUP(E41,J:J,1,0)=E41,"X",""),"") | G41: =IF(J41<>"", INDEX($C$5:$C$1433, MATCH(J41, $E$5:$E$1433, 0)),"") -> 12A11 | H41: =IF(J41<>"", INDEX($D$5:$D$1433, MATCH(J41, $E$5:$E$1433, 0)),"") -> 0 | I41: =IFERROR(IF(J41<>"", INDEX($B$5:$B$1433, MATCH(J41, $E$5:$E$1433, 0)),""),"SAI") -> PHAN THỊ MỸ TIÊN | J41: 32000467 | K41: 6:21:34 AM | L41: =IFERROR(IF($N$5="Sáng",IF(MID(K41,2,7)-MID($L$2,2,7)>0,"Trễ",""),IF(MID(K41,2,7)-MID($Q$2,2,7)>0,"Trễ","")),"") | M41: =IFERROR(IF($N$5="Sáng",MID(K41,2,7)-MID($L$2,2,7),MID(K41,2,7)-MID($Q$2,2,7)),"") -> -0.026689148 | Q41: =IF(B41<>"",IF(AND(P41="",F41=""),"Không phép ",""),"") -> Không phép | R41: =UPPER(B41) -> NGUYỄN LÊ GIA THỊNH | S41: 2026-2029 | T41: =IFERROR(IF(J41<>"", INDEX($S$5:$S$1433, MATCH(J41, $E$5:$E$1433, 0)),""),"") -> 2024-2027 | U41: 27/01/2011 | V41: =IFERROR(IF(J41<>"", INDEX($U$5:$U$1433, MATCH(J41, $E$5:$E$1433, 0)),""),"") -> 39847 | Y41: =Y40+10 -> 330000360 | Z41: =LEFT(Y41,8) -> 33000036 | AA41: THỊNH
A42: =IF(B42<>"",A41+1,"") -> 38 | B42: VÕ GIA THỊNH | C42: 10A1 | D42: 33000037 | E42: 19519387 | F42: =IFERROR(IF(VLOOKUP(E42,J:J,1,0)=E42,"X",""),"") | G42: =IF(J42<>"", INDEX($C$5:$C$1433, MATCH(J42, $E$5:$E$1433, 0)),"") -> 12A11 | H42: =IF(J42<>"", INDEX($D$5:$D$1433, MATCH(J42, $E$5:$E$1433, 0)),"") -> 0 | I42: =IFERROR(IF(J42<>"", INDEX($B$5:$B$1433, MATCH(J42, $E$5:$E$1433, 0)),""),"SAI") -> PHAN THỊ MỸ TIÊN | J42: 32000467 | K42: 6:21:35 AM | L42: =IFERROR(IF($N$5="Sáng",IF(MID(K42,2,7)-MID($L$2,2,7)>0,"Trễ",""),IF(MID(K42,2,7)-MID($Q$2,2,7)>0,"Trễ","")),"") | M42: =IFERROR(IF($N$5="Sáng",MID(K42,2,7)-MID($L$2,2,7),MID(K42,2,7)-MID($Q$2,2,7)),"") -> -0.026677574 | Q42: =IF(B42<>"",IF(AND(P42="",F42=""),"Không phép ",""),"") -> Không phép | R42: =UPPER(B42) -> VÕ GIA THỊNH | S42: 2026-2029 | T42: =IFERROR(IF(J42<>"", INDEX($S$5:$S$1433, MATCH(J42, $E$5:$E$1433, 0)),""),"") -> 2024-2027 | U42: 16/02/2011 | V42: =IFERROR(IF(J42<>"", INDEX($U$5:$U$1433, MATCH(J42, $E$5:$E$1433, 0)),""),"") -> 39847 | Y42: =Y41+10 -> 330000370 | Z42: =LEFT(Y42,8) -> 33000037 | AA42: THỊNH
A43: =IF(B43<>"",A42+1,"") -> 39 | B43: LƯ TRẦN MINH THƯ | C43: 10A1 | D43: 33000038 | E43: 20646027 | F43: =IFERROR(IF(VLOOKUP(E43,J:J,1,0)=E43,"X",""),"") | G43: =IF(J43<>"", INDEX($C$5:$C$1433, MATCH(J43, $E$5:$E$1433, 0)),"") -> 12A2 | H43: =IF(J43<>"", INDEX($D$5:$D$1433, MATCH(J43, $E$5:$E$1433, 0)),"") -> 0 | I43: =IFERROR(IF(J43<>"", INDEX($B$5:$B$1433, MATCH(J43, $E$5:$E$1433, 0)),""),"SAI") -> TRẦN BẢO HÂN | J43: 32000059 | K43: 6:22:03 AM | L43: =IFERROR(IF($N$5="Sáng",IF(MID(K43,2,7)-MID($L$2,2,7)>0,"Trễ",""),IF(MID(K43,2,7)-MID($Q$2,2,7)>0,"Trễ","")),"") | M43: =IFERROR(IF($N$5="Sáng",MID(K43,2,7)-MID($L$2,2,7),MID(K43,2,7)-MID($Q$2,2,7)),"") -> -0.0263535 | Q43: =IF(B43<>"",IF(AND(P43="",F43=""),"Không phép ",""),"") -> Không phép | R43: =UPPER(B43) -> LƯ TRẦN MINH THƯ | S43: 2026-2029 | T43: =IFERROR(IF(J43<>"", INDEX($S$5:$S$1433, MATCH(J43, $E$5:$E$1433, 0)),""),"") -> 2024-2027 | U43: 21/12/2011 | V43: =IFERROR(IF(J43<>"", INDEX($U$5:$U$1433, MATCH(J43, $E$5:$E$1433, 0)),""),"") -> 21/03/2009 | Y43: =Y42+10 -> 330000380 | Z43: =LEFT(Y43,8) -> 33000038 | AA43: THƯ
A44: =IF(B44<>"",A43+1,"") -> 40 | B44: NGUYỄN ĐẶNG MINH THƯ | C44: 10A1 | D44: 33000039 | E44: 20540187 | F44: =IFERROR(IF(VLOOKUP(E44,J:J,1,0)=E44,"X",""),"") | G44: =IF(J44<>"", INDEX($C$5:$C$1433, MATCH(J44, $E$5:$E$1433, 0)),"") -> 12A2 | H44: =IF(J44<>"", INDEX($D$5:$D$1433, MATCH(J44, $E$5:$E$1433, 0)),"") -> 0 | I44: =IFERROR(IF(J44<>"", INDEX($B$5:$B$1433, MATCH(J44, $E$5:$E$1433, 0)),""),"SAI") -> TRẦN BẢO HÂN | J44: 32000059 | K44: 6:22:04 AM | L44: =IFERROR(IF($N$5="Sáng",IF(MID(K44,2,7)-MID($L$2,2,7)>0,"Trễ",""),IF(MID(K44,2,7)-MID($Q$2,2,7)>0,"Trễ","")),"") | M44: =IFERROR(IF($N$5="Sáng",MID(K44,2,7)-MID($L$2,2,7),MID(K44,2,7)-MID($Q$2,2,7)),"") -> -0.026341926 | Q44: =IF(B44<>"",IF(AND(P44="",F44=""),"Không phép ",""),"") -> Không phép | R44: =UPPER(B44) -> NGUYỄN ĐẶNG MINH THƯ | S44: 2026-2029 | T44: =IFERROR(IF(J44<>"", INDEX($S$5:$S$1433, MATCH(J44, $E$5:$E$1433, 0)),""),"") -> 2024-2027 | U44: 19/7/2011 | V44: =IFERROR(IF(J44<>"", INDEX($U$5:$U$1433, MATCH(J44, $E$5:$E$1433, 0)),""),"") -> 21/03/2009 | Y44: =Y43+10 -> 330000390 | Z44: =LEFT(Y44,8) -> 33000039 | AA44: THƯ
A45: =IF(B45<>"",A44+1,"") -> 41 | B45: TRƯƠNG NGỌC ANH THƯ | C45: 10A1 | D45: 33000040 | E45: 19861003 | F45: =IFERROR(IF(VLOOKUP(E45,J:J,1,0)=E45,"X",""),"") | G45: =IF(J45<>"", INDEX($C$5:$C$1433, MATCH(J45, $E$5:$E$1433, 0)),"") -> 12A2 | H45: =IF(J45<>"", INDEX($D$5:$D$1433, MATCH(J45, $E$5:$E$1433, 0)),"") -> 0 | I45: =IFERROR(IF(J45<>"", INDEX($B$5:$B$1433, MATCH(J45, $E$5:$E$1433, 0)),""),"SAI") -> TRẦN BẢO HÂN | J45: 32000059 | K45: 6:22:05 AM | L45: =IFERROR(IF($N$5="Sáng",IF(MID(K45,2,7)-MID($L$2,2,7)>0,"Trễ",""),IF(MID(K45,2,7)-MID($Q$2,2,7)>0,"Trễ","")),"") | M45: =IFERROR(IF($N$5="Sáng",MID(K45,2,7)-MID($L$2,2,7),MID(K45,2,7)-MID($Q$2,2,7)),"") -> -0.026330352 | Q45: =IF(B45<>"",IF(AND(P45="",F45=""),"Không phép ",""),"") -> Không phép | R45: =UPPER(B45) -> TRƯƠNG NGỌC ANH THƯ | S45: 2026-2029 | T45: =IFERROR(IF(J45<>"", INDEX($S$5:$S$1433, MATCH(J45, $E$5:$E$1433, 0)),""),"") -> 2024-2027 | U45: 25/4/2011 | V45: =IFERROR(IF(J45<>"", INDEX($U$5:$U$1433, MATCH(J45, $E$5:$E$1433, 0)),""),"") -> 21/03/2009 | Y45: =Y44+10 -> 330000400 | Z45: =LEFT(Y45,8) -> 33000040 | AA45: THƯ
A46: =IF(B46<>"",A45+1,"") -> 42 | B46: VÕ THỊ MINH THƯ | C46: 10A1 | D46: 33000041 | E46: 19139803 | F46: =IFERROR(IF(VLOOKUP(E46,J:J,1,0)=E46,"X",""),"") | G46: =IF(J46<>"", INDEX($C$5:$C$1433, MATCH(J46, $E$5:$E$1433, 0)),"") -> 11A3 | H46: =IF(J46<>"", INDEX($D$5:$D$1433, MATCH(J46, $E$5:$E$1433, 0)),"") -> 0 | I46: =IFERROR(IF(J46<>"", INDEX($B$5:$B$1433, MATCH(J46, $E$5:$E$1433, 0)),""),"SAI") -> ĐỖ QUỐC VIỆT | J46: 32000647 | K46: 6:22:06 AM | L46: =IFERROR(IF($N$5="Sáng",IF(MID(K46,2,7)-MID($L$2,2,7)>0,"Trễ",""),IF(MID(K46,2,7)-MID($Q$2,2,7)>0,"Trễ","")),"") | M46: =IFERROR(IF($N$5="Sáng",MID(K46,2,7)-MID($L$2,2,7),MID(K46,2,7)-MID($Q$2,2,7)),"") -> -0.026318778 | Q46: =IF(B46<>"",IF(AND(P46="",F46=""),"Không phép ",""),"") -> Không phép | R46: =UPPER(B46) -> VÕ THỊ MINH THƯ | S46: 2026-2029 | T46: =IFERROR(IF(J46<>"", INDEX($S$5:$S$1433, MATCH(J46, $E$5:$E$1433, 0)),""),"") -> 2025-2028 | U46: 02/3/2011 | V46: =IFERROR(IF(J46<>"", INDEX($U$5:$U$1433, MATCH(J46, $E$5:$E$1433, 0)),""),"") -> 24/8/2010 | Y46: =Y45+10 -> 330000410 | Z46: =LEFT(Y46,8) -> 33000041 | AA46: THƯ
A47: =IF(B47<>"",A46+1,"") -> 43 | B47: NGUYỄN LÂM THUẬN | C47: 10A1 | D47: 33000042 | E47: 17747115 | F47: =IFERROR(IF(VLOOKUP(E47,J:J,1,0)=E47,"X",""),"") | G47: =IF(J47<>"", INDEX($C$5:$C$1433, MATCH(J47, $E$5:$E$1433, 0)),"") -> 12A6 | H47: =IF(J47<>"", INDEX($D$5:$D$1433, MATCH(J47, $E$5:$E$1433, 0)),"") -> 0 | I47: =IFERROR(IF(J47<>"", INDEX($B$5:$B$1433, MATCH(J47, $E$5:$E$1433, 0)),""),"SAI") -> TRẦN THANH TUẤN | J47: 32000260 | K47: 6:22:30 AM | L47: =IFERROR(IF($N$5="Sáng",IF(MID(K47,2,7)-MID($L$2,2,7)>0,"Trễ",""),IF(MID(K47,2,7)-MID($Q$2,2,7)>0,"Trễ","")),"") | M47: =IFERROR(IF($N$5="Sáng",MID(K47,2,7)-MID($L$2,2,7),MID(K47,2,7)-MID($Q$2,2,7)),"") -> -0.026041 | Q47: =IF(B47<>"",IF(AND(P47="",F47=""),"Không phép ",""),"") -> Không phép | R47: =UPPER(B47) -> NGUYỄN LÂM THUẬN | S47: 2026-2029 | T47: =IFERROR(IF(J47<>"", INDEX($S$5:$S$1433, MATCH(J47, $E$5:$E$1433, 0)),""),"") -> 2024-2027 | U47: 18/3/2010 | V47: =IFERROR(IF(J47<>"", INDEX($U$5:$U$1433, MATCH(J47, $E$5:$E$1433, 0)),""),"") -> 15/10/2009 | Y47: =Y46+10 -> 330000420 | Z47: =LEFT(Y47,8) -> 33000042 | AA47: THUẬN
A48: =IF(B48<>"",A47+1,"") -> 44 | B48: LÊ PHÚC TƯỜNG | C48: 10A1 | D48: 33000043 | E48: 20506555 | F48: =IFERROR(IF(VLOOKUP(E48,J:J,1,0)=E48,"X",""),"") | G48: =IF(J48<>"", INDEX($C$5:$C$1433, MATCH(J48, $E$5:$E$1433, 0)),"") -> 12A6 | H48: =IF(J48<>"", INDEX($D$5:$D$1433, MATCH(J48, $E$5:$E$1433, 0)),"") -> 0 | I48: =IFERROR(IF(J48<>"", INDEX($B$5:$B$1433, MATCH(J48, $E$5:$E$1433, 0)),""),"SAI") -> TRẦN THANH TUẤN | J48: 32000260 | K48: 6:22:31 AM | L48: =IFERROR(IF($N$5="Sáng",IF(MID(K48,2,7)-MID($L$2,2,7)>0,"Trễ",""),IF(MID(K48,2,7)-MID($Q$2,2,7)>0,"Trễ","")),"") | M48: =IFERROR(IF($N$5="Sáng",MID(K48,2,7)-MID($L$2,2,7),MID(K48,2,7)-MID($Q$2,2,7)),"") -> -0.026029426 | Q48: =IF(B48<>"",IF(AND(P48="",F48=""),"Không phép ",""),"") -> Không phép | R48: =UPPER(B48) -> LÊ PHÚC TƯỜNG | S48: 2026-2029 | T48: =IFERROR(IF(J48<>"", INDEX($S$5:$S$1433, MATCH(J48, $E$5:$E$1433, 0)),""),"") -> 2024-2027 | U48: 16/10/2011 | V48: =IFERROR(IF(J48<>"", INDEX($U$5:$U$1433, MATCH(J48, $E$5:$E$1433, 0)),""),"") -> 15/10/2009 | Y48: =Y47+10 -> 330000430 | Z48: =LEFT(Y48,8) -> 33000043 | AA48: TƯỜNG
A49: =IF(B49<>"",A48+1,"") -> 45 | B49: VÕ NGỌC NHƯ Ý | C49: 10A1 | D49: 33000044 | E49: 20628043 | F49: =IFERROR(IF(VLOOKUP(E49,J:J,1,0)=E49,"X",""),"") | G49: =IF(J49<>"", INDEX($C$5:$C$1433, MATCH(J49, $E$5:$E$1433, 0)),"") -> 12A6 | H49: =IF(J49<>"", INDEX($D$5:$D$1433, MATCH(J49, $E$5:$E$1433, 0)),"") -> 0 | I49: =IFERROR(IF(J49<>"", INDEX($B$5:$B$1433, MATCH(J49, $E$5:$E$1433, 0)),""),"SAI") -> MAI NGUYỄN MINH NHẬT | J49: 32000242 | K49: 6:22:39 AM | L49: =IFERROR(IF($N$5="Sáng",IF(MID(K49,2,7)-MID($L$2,2,7)>0,"Trễ",""),IF(MID(K49,2,7)-MID($Q$2,2,7)>0,"Trễ","")),"") | M49: =IFERROR(IF($N$5="Sáng",MID(K49,2,7)-MID($L$2,2,7),MID(K49,2,7)-MID($Q$2,2,7)),"") -> -0.025936833 | Q49: =IF(B49<>"",IF(AND(P49="",F49=""),"Không phép ",""),"") -> Không phép | R49: =UPPER(B49) -> VÕ NGỌC NHƯ Ý | S49: 2026-2029 | T49: =IFERROR(IF(J49<>"", INDEX($S$5:$S$1433, MATCH(J49, $E$5:$E$1433, 0)),""),"") -> 2024-2027 | U49: 26/3/2011 | V49: =IFERROR(IF(J49<>"", INDEX($U$5:$U$1433, MATCH(J49, $E$5:$E$1433, 0)),""),"") -> 22/12/2009 | Y49: =Y48+10 -> 330000440 | Z49: =LEFT(Y49,8) -> 33000044 | AA49: Ý
A50: =IF(B50<>"",A49+1,"") -> 46 | B50: LÊ NGỌC HẢI YẾN | C50: 10A1 | D50: 33000045 | E50: 19148971 | F50: =IFERROR(IF(VLOOKUP(E50,J:J,1,0)=E50,"X",""),"") | G50: =IF(J50<>"", INDEX($C$5:$C$1433, MATCH(J50, $E$5:$E$1433, 0)),"") -> 12A6 | H50: =IF(J50<>"", INDEX($D$5:$D$1433, MATCH(J50, $E$5:$E$1433, 0)),"") -> 0 | I50: =IFERROR(IF(J50<>"", INDEX($B$5:$B$1433, MATCH(J50, $E$5:$E$1433, 0)),""),"SAI") -> VU HOÀNG THÔNG | J50: 32000251 | K50: 6:22:41 AM | L50: =IFERROR(IF($N$5="Sáng",IF(MID(K50,2,7)-MID($L$2,2,7)>0,"Trễ",""),IF(MID(K50,2,7)-MID($Q$2,2,7)>0,"Trễ","")),"") | M50: =IFERROR(IF($N$5="Sáng",MID(K50,2,7)-MID($L$2,2,7),MID(K50,2,7)-MID($Q$2,2,7)),"") -> -0.025913685 | Q50: =IF(B50<>"",IF(AND(P50="",F50=""),"Không phép ",""),"") -> Không phép | R50: =UPPER(B50) -> LÊ NGỌC HẢI YẾN | S50: 2026-2029 | T50: =IFERROR(IF(J50<>"", INDEX($S$5:$S$1433, MATCH(J50, $E$5:$E$1433, 0)),""),"") -> 2024-2027 | U50: 16/5/2011 | V50: =IFERROR(IF(J50<>"", INDEX($U$5:$U$1433, MATCH(J50, $E$5:$E$1433, 0)),""),"") -> 39969 | Y50: =Y49+10 -> 330000450 | Z50: =LEFT(Y50,8) -> 33000045 | AA50: YẾN
... A107: =IF(B107<>"",A106+1,"") -> 103 | B107: LƯƠNG LƯU MỸ KHÁNH | C107: 10A11 | D107: 33000102 | E107: 12725531 | F107: =IFERROR(IF(VLOOKUP(E107,J:J,1,0)=E107,"X",""),"") | G107: =IF(J107<>"", INDEX($C$5:$C$1433, MATCH(J107, $E$5:$E$1433, 0)),"") -> 12A3 | H107: =IF(J107<>"", INDEX($D$5:$D$1433, MATCH(J107, $E$5:$E$1433, 0)),"") -> 0 | I107: =IFERROR(IF(J107<>"", INDEX($B$5:$B$1433, MATCH(J107, $E$5:$E$1433, 0)),""),"SAI") -> NGUYỄN THANH THIÊN | J107: 32000125 | K107: 6:28:01 AM | L107: =IFERROR(IF($N$5="Sáng",IF(MID(K107,2,7)-MID($L$2,2,7)>0,"Trễ",""),IF(MID(K107,2,7)-MID($Q$2,2,7)>0,"Trễ","")),"") | M107: =IFERROR(IF($N$5="Sáng",MID(K107,2,7)-MID($L$2,2,7),MID(K107,2,7)-MID($Q$2,2,7)),"") -> -0.022209981 | Q107: =IF(B107<>"",IF(AND(P107="",F107=""),"Không phép ",""),"") -> Không phép | R107: =UPPER(B107) -> LƯƠNG LƯU MỸ KHÁNH | S107: 2026-2029 | T107: =IFERROR(IF(J107<>"", INDEX($S$5:$S$1433, MATCH(J107, $E$5:$E$1433, 0)),""),"") -> 2024-2027 | U107: 02/3/2011 | V107: =IFERROR(IF(J107<>"", INDEX($U$5:$U$1433, MATCH(J107, $E$5:$E$1433, 0)),""),"") -> 40119 | Y107: =Y106+10 -> 330001020 | Z107: =LEFT(Y107,8) -> 33000102 | AA107: KHÁNH
A108: =IF(B108<>"",A107+1,"") -> 104 | B108: LÂM KHÔI | C108: 10A11 | D108: 33000103 | E108: 19562107 | G108: =IF(J108<>"", INDEX($C$5:$C$1433, MATCH(J108, $E$5:$E$1433, 0)),"") -> 12A7 | H108: =IF(J108<>"", INDEX($D$5:$D$1433, MATCH(J108, $E$5:$E$1433, 0)),"") -> 0 | I108: =IFERROR(IF(J108<>"", INDEX($B$5:$B$1433, MATCH(J108, $E$5:$E$1433, 0)),""),"SAI") -> NGUYỄN CHÍ TƯỜNG | J108: 32000306 | K108: 6:28:03 AM | L108: =IFERROR(IF($N$5="Sáng",IF(MID(K108,2,7)-MID($L$2,2,7)>0,"Trễ",""),IF(MID(K108,2,7)-MID($Q$2,2,7)>0,"Trễ","")),"") | M108: =IFERROR(IF($N$5="Sáng",MID(K108,2,7)-MID($L$2,2,7),MID(K108,2,7)-MID($Q$2,2,7)),"") -> -0.022186833 | Q108: =IF(B108<>"",IF(AND(P108="",F108=""),"Không phép ",""),"") -> Không phép | R108: =UPPER(B108) -> LÂM KHÔI | S108: 2026-2029 | T108: =IFERROR(IF(J108<>"", INDEX($S$5:$S$1433, MATCH(J108, $E$5:$E$1433, 0)),""),"") -> 2024-2027 | U108: 02/12/2011 | V108: =IFERROR(IF(J108<>"", INDEX($U$5:$U$1433, MATCH(J108, $E$5:$E$1433, 0)),""),"") -> 16/01/2009 | Y108: =Y107+10 -> 330001030 | Z108: =LEFT(Y108,8) -> 33000103 | AA108: KHÔI
A109: =IF(B109<>"",A108+1,"") -> 105 | B109: DANH KIỆT | C109: 10A11 | D109: 33000104 | E109: 20605435 | G109: =IF(J109<>"", INDEX($C$5:$C$1433, MATCH(J109, $E$5:$E$1433, 0)),"") -> 12A7 | H109: =IF(J109<>"", INDEX($D$5:$D$1433, MATCH(J109, $E$5:$E$1433, 0)),"") -> 0 | I109: =IFERROR(IF(J109<>"", INDEX($B$5:$B$1433, MATCH(J109, $E$5:$E$1433, 0)),""),"SAI") -> NGUYỄN CHÍ TƯỜNG | J109: 32000306 | K109: 6:28:04 AM | L109: =IFERROR(IF($N$5="Sáng",IF(MID(K109,2,7)-MID($L$2,2,7)>0,"Trễ",""),IF(MID(K109,2,7)-MID($Q$2,2,7)>0,"Trễ","")),"") | M109: =IFERROR(IF($N$5="Sáng",MID(K109,2,7)-MID($L$2,2,7),MID(K109,2,7)-MID($Q$2,2,7)),"") -> -0.022175259 | Q109: =IF(B109<>"",IF(AND(P109="",F109=""),"Không phép ",""),"") -> Không phép | R109: =UPPER(B109) -> DANH KIỆT | S109: 2026-2029 | T109: =IFERROR(IF(J109<>"", INDEX($S$5:$S$1433, MATCH(J109, $E$5:$E$1433, 0)),""),"") -> 2024-2027 | U109: 06/12/2010 | V109: =IFERROR(IF(J109<>"", INDEX($U$5:$U$1433, MATCH(J109, $E$5:$E$1433, 0)),""),"") -> 16/01/2009 | Y109: =Y108+10 -> 330001040 | Z109: =LEFT(Y109,8) -> 33000104 | AA109: KIỆT
A110: =IF(B110<>"",A109+1,"") -> 106 | B110: TRẦN ANH KIỆT | C110: 10A11 | D110: 33000105 | E110: 19027595 | G110: =IF(J110<>"", INDEX($C$5:$C$1433, MATCH(J110, $E$5:$E$1433, 0)),"") -> 12A7 | H110: =IF(J110<>"", INDEX($D$5:$D$1433, MATCH(J110, $E$5:$E$1433, 0)),"") -> 0 | I110: =IFERROR(IF(J110<>"", INDEX($B$5:$B$1433, MATCH(J110, $E$5:$E$1433, 0)),""),"SAI") -> NGUYỄN CHÍ TƯỜNG | J110: 32000306 | K110: 6:28:05 AM | L110: =IFERROR(IF($N$5="Sáng",IF(MID(K110,2,7)-MID($L$2,2,7)>0,"Trễ",""),IF(MID(K110,2,7)-MID($Q$2,2,7)>0,"Trễ","")),"") | M110: =IFERROR(IF($N$5="Sáng",MID(K110,2,7)-MID($L$2,2,7),MID(K110,2,7)-MID($Q$2,2,7)),"") -> -0.022163685 | R110: =UPPER(B110) -> TRẦN ANH KIỆT | S110: 2026-2029 | T110: =IFERROR(IF(J110<>"", INDEX($S$5:$S$1433, MATCH(J110, $E$5:$E$1433, 0)),""),"") -> 2024-2027 | U110: 12/6/2010 | V110: =IFERROR(IF(J110<>"", INDEX($U$5:$U$1433, MATCH(J110, $E$5:$E$1433, 0)),""),"") -> 16/01/2009 | Y110: =Y109+10 -> 330001050 | Z110: =LEFT(Y110,8) -> 33000105 | AA110: KIỆT
A111: =IF(B111<>"",A110+1,"") -> 107 | B111: LÊ NGỌC THIÊN KIM | C111: 10A11 | D111: 33000106 | E111: 20604603 | G111: =IF(J111<>"", INDEX($C$5:$C$1433, MATCH(J111, $E$5:$E$1433, 0)),"") -> 12A5 | H111: =IF(J111<>"", INDEX($D$5:$D$1433, MATCH(J111, $E$5:$E$1433, 0)),"") -> 0 | I111: =IFERROR(IF(J111<>"", INDEX($B$5:$B$1433, MATCH(J111, $E$5:$E$1433, 0)),""),"SAI") -> NGUYỄN THỊ NGỌC TRÚC | J111: 32000220 | K111: 6:28:11 AM | L111: =IFERROR(IF($N$5="Sáng",IF(MID(K111,2,7)-MID($L$2,2,7)>0,"Trễ",""),IF(MID(K111,2,7)-MID($Q$2,2,7)>0,"Trễ","")),"") | M111: =IFERROR(IF($N$5="Sáng",MID(K111,2,7)-MID($L$2,2,7),MID(K111,2,7)-MID($Q$2,2,7)),"") -> -0.022094241 | S111: 2026-2029 | T111: =IFERROR(IF(J111<>"", INDEX($S$5:$S$1433, MATCH(J111, $E$5:$E$1433, 0)),""),"") -> 2024-2027 | U111: 07/6/2011 | V111: =IFERROR(IF(J111<>"", INDEX($U$5:$U$1433, MATCH(J111, $E$5:$E$1433, 0)),""),"") -> 17/05/2009 | Y111: =Y110+10 -> 330001060 | Z111: =LEFT(Y111,8) -> 33000106 | AA111: KIM
A112: =IF(B112<>"",A111+1,"") -> 108 | B112: PHAN NGỌC MỸ KIM | C112: 10A11 | D112: 33000107 | E112: 20626651 | G112: =IF(J112<>"", INDEX($C$5:$C$1433, MATCH(J112, $E$5:$E$1433, 0)),"") -> 11A9 | H112: =IF(J112<>"", INDEX($D$5:$D$1433, MATCH(J112, $E$5:$E$1433, 0)),"") -> 0 | I112: =IFERROR(IF(J112<>"", INDEX($B$5:$B$1433, MATCH(J112, $E$5:$E$1433, 0)),""),"SAI") -> LÊ HỒNG PHÚC | J112: 32000890 | K112: 6:28:32 AM | L112: =IFERROR(IF($N$5="Sáng",IF(MID(K112,2,7)-MID($L$2,2,7)>0,"Trễ",""),IF(MID(K112,2,7)-MID($Q$2,2,7)>0,"Trễ","")),"") | M112: =IFERROR(IF($N$5="Sáng",MID(K112,2,7)-MID($L$2,2,7),MID(K112,2,7)-MID($Q$2,2,7)),"") -> -0.021851185 | S112: 2026-2029 | T112: =IFERROR(IF(J112<>"", INDEX($S$5:$S$1433, MATCH(J112, $E$5:$E$1433, 0)),""),"") -> 2025-2028 | U112: 20/5/2011 | V112: =IFERROR(IF(J112<>"", INDEX($U$5:$U$1433, MATCH(J112, $E$5:$E$1433, 0)),""),"") -> 22/02/2010 | Y112: =Y111+10 -> 330001070 | Z112: =LEFT(Y112,8) -> 33000107 | AA112: KIM
A113: =IF(B113<>"",A112+1,"") -> 109 | B113: DANH THỊ THANH LAM | C113: 10A11 | D113: 33000108 | E113: 19454539 | G113: =IF(J113<>"", INDEX($C$5:$C$1433, MATCH(J113, $E$5:$E$1433, 0)),"") -> 12A5 | H113: =IF(J113<>"", INDEX($D$5:$D$1433, MATCH(J113, $E$5:$E$1433, 0)),"") -> 0 | I113: =IFERROR(IF(J113<>"", INDEX($B$5:$B$1433, MATCH(J113, $E$5:$E$1433, 0)),""),"SAI") -> NGUYỄN THỊ YẾN NHI | J113: 32000208 | K113: 6:28:34 AM | L113: =IFERROR(IF($N$5="Sáng",IF(MID(K113,2,7)-MID($L$2,2,7)>0,"Trễ",""),IF(MID(K113,2,7)-MID($Q$2,2,7)>0,"Trễ","")),"") | M113: =IFERROR(IF($N$5="Sáng",MID(K113,2,7)-MID($L$2,2,7),MID(K113,2,7)-MID($Q$2,2,7)),"") -> -0.021828037 | S113: 2026-2029 | T113: =IFERROR(IF(J113<>"", INDEX($S$5:$S$1433, MATCH(J113, $E$5:$E$1433, 0)),""),"") -> 2024-2027 | U113: 18/3/2011 | V113: =IFERROR(IF(J113<>"", INDEX($U$5:$U$1433, MATCH(J113, $E$5:$E$1433, 0)),""),"") -> 40122 | Y113: =Y112+10 -> 330001080 | Z113: =LEFT(Y113,8) -> 33000108 | AA113: LAM
A114: =IF(B114<>"",A113+1,"") -> 110 | B114: NGUYỄN VÕ THÙY LÂM | C114: 10A11 | D114: 33000109 | E114: 20635643 | G114: =IF(J114<>"", INDEX($C$5:$C$1433, MATCH(J114, $E$5:$E$1433, 0)),"") -> 11A8 | H114: =IF(J114<>"", INDEX($D$5:$D$1433, MATCH(J114, $E$5:$E$1433, 0)),"") -> 0 | I114: =IFERROR(IF(J114<>"", INDEX($B$5:$B$1433, MATCH(J114, $E$5:$E$1433, 0)),""),"SAI") -> LÂM QUỐC HUY | J114: 32000832 | K114: 6:28:38 AM | L114: =IFERROR(IF($N$5="Sáng",IF(MID(K114,2,7)-MID($L$2,2,7)>0,"Trễ",""),IF(MID(K114,2,7)-MID($Q$2,2,7)>0,"Trễ","")),"") | M114: =IFERROR(IF($N$5="Sáng",MID(K114,2,7)-MID($L$2,2,7),MID(K114,2,7)-MID($Q$2,2,7)),"") -> -0.021781741 | S114: 2026-2029 | T114: =IFERROR(IF(J114<>"", INDEX($S$5:$S$1433, MATCH(J114, $E$5:$E$1433, 0)),""),"") -> 2025-2028 | U114: 15/3/2011 | V114: =IFERROR(IF(J114<>"", INDEX($U$5:$U$1433, MATCH(J114, $E$5:$E$1433, 0)),""),"") -> 17/02/2010 | Y114: =Y113+10 -> 330001090 | Z114: =LEFT(Y114,8) -> 33000109 | AA114: LÂM
A115: =IF(B115<>"",A114+1,"") -> 111 | B115: HUỲNH THỊ THU LAN | C115: 10A11 | D115: 33000110 | E115: 19062651 | G115: =IF(J115<>"", INDEX($C$5:$C$1433, MATCH(J115, $E$5:$E$1433, 0)),"") -> 12A10 | H115: =IF(J115<>"", INDEX($D$5:$D$1433, MATCH(J115, $E$5:$E$1433, 0)),"") -> 0 | I115: =IFERROR(IF(J115<>"", INDEX($B$5:$B$1433, MATCH(J115, $E$5:$E$1433, 0)),""),"SAI") -> NGUYỄN THỊ THÚY HƯƠNG | J115: 32000416 | K115: 6:28:41 AM | L115: =IFERROR(IF($N$5="Sáng",IF(MID(K115,2,7)-MID($L$2,2,7)>0,"Trễ",""),IF(MID(K115,2,7)-MID($Q$2,2,7)>0,"Trễ","")),"") | M115: =IFERROR(IF($N$5="Sáng",MID(K115,2,7)-MID($L$2,2,7),MID(K115,2,7)-MID($Q$2,2,7)),"") -> -0.021747019 | S115: 2026-2029 | T115: =IFERROR(IF(J115<>"", INDEX($S$5:$S$1433, MATCH(J115, $E$5:$E$1433, 0)),""),"") -> 2024-2027 | U115: 08/8/2011 | V115: =IFERROR(IF(J115<>"", INDEX($U$5:$U$1433, MATCH(J115, $E$5:$E$1433, 0)),""),"") -> 17/12/2009 | Y115: =Y114+10 -> 330001100 | Z115: =LEFT(Y115,8) -> 33000110 | AA115: LAN
...

Sheet Thongkengay
A1: THỐNG KÊ HỌC SINH VẮNG HỌC NGÀY | G1: 46284
A3: Thống kê học sinh vắng hôm nay
A4: TT | B4: HỌ VÀ TÊN | C4: lớp | D4: Phép | E4: Không phép | F4: ID PHHS | G4: THỐNG KÊ DANH SÁCH VẮNG THEO LỚP | R4: SL vang (zalo) | W4: Tổng số buổi vắng đến hiện tại là: | AE4: SLTRỄ | AF4: T/G TRỄ
A5: =IF(B5<>"",1,"") -> 1 | B5: TRẦN VIẾT BÌNH AN | C5: 10A1 | E5: Không phép | F5: 33000000 | R5: =IF(B5<>"", INDEX($V$8:$V$1491, MATCH(B5, $T$8:$T$1491, 0)),"") -> 3 | S5: THỐNG KÊ TỔNG SỐ BUỔI NGHỈ | AE5: =IF(B5<>"", INDEX($X$8:$X$1491, MATCH(B5, $T$8:$T$1491, 0)),"") -> 0 | AF5: =IF(AH8<>"", INDEX($AJ$8:$AJ$1491, MATCH(AH8, $T$8:$T$1491, 0)),"") -> 0.10461872
A6: =IF(B6<>"",A5+1,"") -> 2 | B6: NGUYỄN THỊ MAI ANH | C6: 10A1 | E6: Không phép | F6: 33000001 | G6: 10A1 | H6: 10A2 | I6: 10A3 | J6: 10A4 | K6: 10A5 | L6: 10A6 | M6: 10A7 | N6: 10A8 | O6: 10A9 | P6: 10A10 | Q6: 10A11 | R6: =IF(B6<>"", INDEX($V$8:$V$1491, MATCH(B6, $T$8:$T$1491, 0)),"") -> 3 | W6: APP TÁC PHONG HỌC SINH (số lần HS vi phạm tác phong) | AE6: =IF(B6<>"", INDEX($X$8:$X$1491, MATCH(B6, $T$8:$T$1491, 0)),"") -> 0 | AF6: =IF(AH9<>"", INDEX($AJ$8:$AJ$1491, MATCH(AH9, $T$8:$T$1491, 0)),"") -> 0.1046303 | AG6: DANH SÁCH TRỄ
A7: =IF(B7<>"",A6+1,"") -> 3 | B7: TRẦN HUỲNH KHÁNH BĂNG | C7: 10A1 | E7: Không phép | F7: 33000002 | G7: =COUNTIF($C$5:$C$1491,G6) -> 44 | H7: =COUNTIF($C$5:$C$1491,H6) -> 35 | I7: =COUNTIF($C$5:$C$1491,I6) -> 46 | J7: =COUNTIF($C$5:$C$1491,J6) -> 40 | K7: =COUNTIF($C$5:$C$1491,K6) -> 44 | L7: =COUNTIF($C$5:$C$1491,L6) -> 43 | M7: =COUNTIF($C$5:$C$1491,M6) -> 41 | N7: =COUNTIF($C$5:$C$1491,N6) -> 45 | ... Q7: =COUNTIF($C$5:$C$1491,Q6) -> 14 | R7: =IF(B7<>"", INDEX($V$8:$V$1491, MATCH(B7, $T$8:$T$1491, 0)),"") -> 3 | S7: TT | T7: HỌ VÀ TÊN | U7: LỚP | V7: SL VẮNG | W7: SL VẮNG1 | X7: SL trễ | Y7: DÉP LÊ | Z7: TÓC | AA7: SON | AB7: NÓI TỤC | AC7: XÃ RÁC | AD7: KHÁC (ghi cụ thể) | AE7: =IF(B7<>"", INDEX($X$8:$X$1491, MATCH(B7, $T$8:$T$1491, 0)),"") -> 0 | AF7: =IF(AH10<>"", INDEX($AJ$8:$AJ$1491, MATCH(AH10, $T$8:$T$1491, 0)),"") -> 0.142049 | AG7: TT | AH7: TÊN HS | AI7: LỚP | AJ7: TG TRỄ | AK7: Sl trễ
A8: =IF(B8<>"",A7+1,"") -> 4 | B8: TRẦN NGUYỄN THẾ BẢO | C8: 10A1 | E8: Không phép | F8: 33000003 | G8: 11A1 | H8: 11A2 | I8: 11A3 | J8: 11A4 | K8: 11A5 | L8: 11A6 | M8: 11A7 | N8: 11A8 | O8: 11A9 | P8: 11A10 | Q8: 11A11 | R8: =IF(B8<>"", INDEX($V$8:$V$1491, MATCH(B8, $T$8:$T$1491, 0)),"") -> 3 | S8: =IF(T8<>"",1,"") -> 1 | T8: =data!B5 -> TRẦN VIẾT BÌNH AN | U8: =data!C5 -> 10A1 | V8: 3 | Y8: ='10a1tr'!H2 -> 0 | Z8: ='10a1tr'!I2 -> 0 | AA8: ='10a1tr'!J2 -> 0 | AB8: ='10a1tr'!K2 -> 0 | AC8: ='10a1tr'!L2 -> 0 | AE8: =IF(B8<>"", INDEX($X$8:$X$1491, MATCH(B8, $T$8:$T$1491, 0)),"") -> 0 | AF8: =IF(AH11<>"", INDEX($AJ$8:$AJ$1491, MATCH(AH11, $T$8:$T$1491, 0)),"") -> 0 | AG8: =IF(AH8<>"",1,"") -> 1 | AH8: VÕ THÚY AN | AI8: 10A3 | AJ8: 0.1205678
A9: =IF(B9<>"",A8+1,"") -> 5 | B9: THÁI AN BÌNH | C9: 10A1 | E9: Không phép | F9: 33000004 | G9: =COUNTIF($C$5:$C$1491,G8) -> 9 | H9: =COUNTIF($C$5:$C$1491,H8) -> 14 | I9: =COUNTIF($C$5:$C$1491,I8) -> 22 | J9: =COUNTIF($C$5:$C$1491,J8) -> 17 | K9: =COUNTIF($C$5:$C$1491,K8) -> 13 | L9: =COUNTIF($C$5:$C$1491,L8) -> 19 | M9: =COUNTIF($C$5:$C$1491,M8) -> 23 | N9: =COUNTIF($C$5:$C$1491,N8) -> 15 | ... Q9: =COUNTIF($C$5:$C$1491,Q8) -> 0 | R9: =IF(B9<>"", INDEX($V$8:$V$1491, MATCH(B9, $T$8:$T$1491, 0)),"") -> 3 | S9: =IF(T9<>"",S8+1,"") -> 2 | T9: =data!B6 -> NGUYỄN THỊ MAI ANH | U9: =data!C6 -> 10A1 | V9: 3 | Y9: ='10a1tr'!H3 -> 0 | Z9: ='10a1tr'!I3 -> 0 | AA9: ='10a1tr'!J3 -> 0 | AB9: ='10a1tr'!K3 -> 0 | AC9: ='10a1tr'!L3 -> 0 | AE9: =IF(B9<>"", INDEX($X$8:$X$1491, MATCH(B9, $T$8:$T$1491, 0)),"") -> 0 | AF9: =IF(AH12<>"", INDEX($AJ$8:$AJ$1491, MATCH(AH12, $T$8:$T$1491, 0)),"") -> 0 | AG9: =IF(AH9<>"",AG8+1, "") -> 2 | AH9: LÊ HUỲNH ANH | AI9: 10A3 | AJ9: 0.12057937
A10: =IF(B10<>"",A9+1,"") -> 6 | B10: TRẦN VŨ NAM BÌNH | C10: 10A1 | E10: Không phép | F10: 33000005 | G10: 12A1 | H10: 12A2 | I10: 12A3 | J10: 12A4 | K10: 12A5 | L10: 12A6 | M10: 12A7 | N10: 12A8 | O10: 12A9 | P10: 12A10 | Q10: 12A11 | R10: =IF(B10<>"", INDEX($V$8:$V$1491, MATCH(B10, $T$8:$T$1491, 0)),"") -> 3 | S10: =IF(T10<>"",S9+1,"") -> 3 | T10: =data!B7 -> TRẦN HUỲNH KHÁNH BĂNG | U10: =data!C7 -> 10A1 | V10: 3 | Y10: ='10a1tr'!H4 -> 0 | Z10: ='10a1tr'!I4 -> 0 | AA10: ='10a1tr'!J4 -> 0 | AB10: ='10a1tr'!K4 -> 0 | AC10: ='10a1tr'!L4 -> 0 | AE10: =IF(B10<>"", INDEX($X$8:$X$1491, MATCH(B10, $T$8:$T$1491, 0)),"") -> 0 | AF10: =IF(AH13<>"", INDEX($AJ$8:$AJ$1491, MATCH(AH13, $T$8:$T$1491, 0)),"") -> 0 | AG10: =IF(AH10<>"",AG9+1, "") -> 3 | AH10: TRIỆU QUỐC BẢO | AI10: 10A3 | AJ10: 0.132894
A11: =IF(B11<>"",A10+1,"") -> 7 | B11: LÝ NGUYỄN KHÁNH DI | C11: 10A1 | E11: Không phép | F11: 33000006 | G11: =COUNTIF($C$5:$C$1491,G10) -> 5 | H11: =COUNTIF($C$5:$C$1491,H10) -> 11 | I11: =COUNTIF($C$5:$C$1491,I10) -> 1 | J11: =COUNTIF($C$5:$C$1491,J10) -> 6 | K11: =COUNTIF($C$5:$C$1491,K10) -> 5 | L11: =COUNTIF($C$5:$C$1491,L10) -> 6 | M11: =COUNTIF($C$5:$C$1491,M10) -> 6 | N11: =COUNTIF($C$5:$C$1491,N10) -> 6 | ... Q11: =COUNTIF($C$5:$C$1491,Q10) -> 1 | R11: =IF(B11<>"", INDEX($V$8:$V$1491, MATCH(B11, $T$8:$T$1491, 0)),"") -> 3 | S11: =IF(T11<>"",S10+1,"") -> 4 | T11: =data!B8 -> TRẦN NGUYỄN THẾ BẢO | U11: =data!C8 -> 10A1 | V11: 3 | Y11: ='10a1tr'!H5 -> 0 | Z11: ='10a1tr'!I5 -> 0 | AA11: ='10a1tr'!J5 -> 0 | AB11: ='10a1tr'!K5 -> 0 | AC11: ='10a1tr'!L5 -> 0 | AE11: =IF(B11<>"", INDEX($X$8:$X$1491, MATCH(B11, $T$8:$T$1491, 0)),"") -> 0 | AF11: =IF(AH14<>"", INDEX($AJ$8:$AJ$1491, MATCH(AH14, $T$8:$T$1491, 0)),"") -> 0 | AG11: =IF(AH11<>"",AG10+1, "") -> 4 | AH11: VÕ DUY THÁI | AI11: 12A10 | AJ11: 1.2240741e-05
A12: =IF(B12<>"",A11+1,"") -> 8 | B12: LÊ NGUYỄN HUYỀN DIỆU | C12: 10A1 | E12: Không phép | F12: 33000007 | G12: TỔNG SỐ: | I12: =SUM(G7:Q7,G9:Q9,G11:P11) -> 674 | R12: =IF(B12<>"", INDEX($V$8:$V$1491, MATCH(B12, $T$8:$T$1491, 0)),"") -> 3 | S12: =IF(T12<>"",S11+1,"") -> 5 | T12: =data!B9 -> THÁI AN BÌNH | U12: =data!C9 -> 10A1 | V12: 3 | Y12: ='10a1tr'!H6 -> 0 | Z12: ='10a1tr'!I6 -> 0 | AA12: ='10a1tr'!J6 -> 0 | AB12: ='10a1tr'!K6 -> 0 | AC12: ='10a1tr'!L6 -> 0 | AE12: =IF(B12<>"", INDEX($X$8:$X$1491, MATCH(B12, $T$8:$T$1491, 0)),"") -> 0 | AF12: =IF(AH15<>"", INDEX($AJ$8:$AJ$1491, MATCH(AH15, $T$8:$T$1491, 0)),"") -> 0 | AG12: =IF(AH12<>"",AG11+1, "") -> 5 | AH12: NGUYỄN VÕ MINH THƯ | AI12: 12A10 | AJ12: 9.3259259e-05
A13: =IF(B13<>"",A12+1,"") -> 9 | B13: HỨA THANH DUNG | C13: 10A1 | E13: Không phép | F13: 33000008 | R13: =IF(B13<>"", INDEX($V$8:$V$1491, MATCH(B13, $T$8:$T$1491, 0)),"") -> 3 | S13: =IF(T13<>"",S12+1,"") -> 6 | T13: =data!B10 -> TRẦN VŨ NAM BÌNH | U13: =data!C10 -> 10A1 | V13: 3 | Y13: ='10a1tr'!H7 -> 0 | Z13: ='10a1tr'!I7 -> 0 | AA13: ='10a1tr'!J7 -> 0 | AB13: ='10a1tr'!K7 -> 0 | AC13: ='10a1tr'!L7 -> 0 | AE13: =IF(B13<>"", INDEX($X$8:$X$1491, MATCH(B13, $T$8:$T$1491, 0)),"") -> 0 | AF13: =IF(AH16<>"", INDEX($AJ$8:$AJ$1491, MATCH(AH16, $T$8:$T$1491, 0)),"") -> 0 | AG13: =IF(AH13<>"",AG12+1, "") -> 6 | AH13: NGUYỄN VŨ BẢO THY | AI13: 12A10 | AJ13: 0.00013955556
A14: =IF(B14<>"",A13+1,"") -> 10 | B14: PHAN NGUYỄN THÙY DƯƠNG | C14: 10A1 | E14: Không phép | F14: 33000009 | R14: =IF(B14<>"", INDEX($V$8:$V$1491, MATCH(B14, $T$8:$T$1491, 0)),"") -> 3 | S14: =IF(T14<>"",S13+1,"") -> 7 | T14: =data!B11 -> LÝ NGUYỄN KHÁNH DI | U14: =data!C11 -> 10A1 | V14: 3 | Y14: ='10a1tr'!H8 -> 0 | Z14: ='10a1tr'!I8 -> 0 | AA14: ='10a1tr'!J8 -> 0 | AB14: ='10a1tr'!K8 -> 0 | AC14: ='10a1tr'!L8 -> 0 | AE14: =IF(B14<>"", INDEX($X$8:$X$1491, MATCH(B14, $T$8:$T$1491, 0)),"") -> 0 | AF14: =IF(AH17<>"", INDEX($AJ$8:$AJ$1491, MATCH(AH17, $T$8:$T$1491, 0)),"") -> 0 | AG14: =IF(AH14<>"",AG13+1, "") -> 7 | AH14: LÊ ĐOÀN BẢO THY | AI14: 12A10 | AJ14: 0.0016326111
A15: =IF(B15<>"",A14+1,"") -> 11 | B15: THÁI LÝ GIA HÂN | C15: 10A1 | E15: Không phép | F15: 33000010 | R15: =IF(B15<>"", INDEX($V$8:$V$1491, MATCH(B15, $T$8:$T$1491, 0)),"") -> 3 | S15: =IF(T15<>"",S14+1,"") -> 8 | T15: =data!B12 -> LÊ NGUYỄN HUYỀN DIỆU | U15: =data!C12 -> 10A1 | V15: 3 | Y15: ='10a1tr'!H9 -> 0 | Z15: ='10a1tr'!I9 -> 0 | AA15: ='10a1tr'!J9 -> 0 | AB15: ='10a1tr'!K9 -> 0 | AC15: ='10a1tr'!L9 -> 0 | AE15: =IF(B15<>"", INDEX($X$8:$X$1491, MATCH(B15, $T$8:$T$1491, 0)),"") -> 0 | AF15: =IF(AH18<>"", INDEX($AJ$8:$AJ$1491, MATCH(AH18, $T$8:$T$1491, 0)),"") -> 0 | AG15: =IF(AH15<>"",AG14+1, "") -> 8 | AH15: ĐẶNG NGUYỄN CÁT TƯỜNG | AI15: 12A10 | AJ15: 0.05089187
A16: =IF(B16<>"",A15+1,"") -> 12 | B16: NGUYỄN THỊ PHƯƠNG HẬU | C16: 10A1 | E16: Không phép | F16: 33000011 | R16: =IF(B16<>"", INDEX($V$8:$V$1491, MATCH(B16, $T$8:$T$1491, 0)),"") -> 3 | S16: =IF(T16<>"",S15+1,"") -> 9 | T16: =data!B13 -> HỨA THANH DUNG | U16: =data!C13 -> 10A1 | V16: 3 | Y16: ='10a1tr'!H10 -> 0 | Z16: ='10a1tr'!I10 -> 0 | AA16: ='10a1tr'!J10 -> 0 | AB16: ='10a1tr'!K10 -> 0 | AC16: ='10a1tr'!L10 -> 0 | AE16: =IF(B16<>"", INDEX($X$8:$X$1491, MATCH(B16, $T$8:$T$1491, 0)),"") -> 0 | AF16: =IF(AH19<>"", INDEX($AJ$8:$AJ$1491, MATCH(AH19, $T$8:$T$1491, 0)),"") -> 0 | AG16: =IF(AH16<>"",AG15+1, "") -> 9 | AH16: NGUYỄN TRỌNG VĨ | AI16: 12A10 | AJ16: 0.11128539
A17: =IF(B17<>"",A16+1,"") -> 13 | B17: TRẦN VĨ HIỆP | C17: 10A1 | E17: Không phép | F17: 33000012 | R17: =IF(B17<>"", INDEX($V$8:$V$1491, MATCH(B17, $T$8:$T$1491, 0)),"") -> 3 | S17: =IF(T17<>"",S16+1,"") -> 10 | T17: =data!B14 -> PHAN NGUYỄN THÙY DƯƠNG | U17: =data!C14 -> 10A1 | V17: 3 | Y17: ='10a1tr'!H11 -> 0 | Z17: ='10a1tr'!I11 -> 0 | AA17: ='10a1tr'!J11 -> 0 | AB17: ='10a1tr'!K11 -> 0 | AC17: ='10a1tr'!L11 -> 0 | AE17: =IF(B17<>"", INDEX($X$8:$X$1491, MATCH(B17, $T$8:$T$1491, 0)),"") -> 0 | AF17: =IF(AH20<>"", INDEX($AJ$8:$AJ$1491, MATCH(AH20, $T$8:$T$1491, 0)),"") -> 0 | AG17: =IF(AH17<>"",AG16+1, "") -> 10 | AH17: HUỲNH QUỐC VINH | AI17: 12A10 | AJ17: 0.147963
A18: =IF(B18<>"",A17+1,"") -> 14 | B18: VÕ LÊ GIA HUY | C18: 10A1 | E18: Không phép | F18: 33000013 | R18: =IF(B18<>"", INDEX($V$8:$V$1491, MATCH(B18, $T$8:$T$1491, 0)),"") -> 3 | S18: =IF(T18<>"",S17+1,"") -> 11 | T18: =data!B15 -> THÁI LÝ GIA HÂN | U18: =data!C15 -> 10A1 | V18: 3 | Y18: ='10a1tr'!H12 -> 0 | Z18: ='10a1tr'!I12 -> 0 | AA18: ='10a1tr'!J12 -> 0 | AB18: ='10a1tr'!K12 -> 0 | AC18: ='10a1tr'!L12 -> 0 | AE18: =IF(B18<>"", INDEX($X$8:$X$1491, MATCH(B18, $T$8:$T$1491, 0)),"") -> 0 | AF18: =IF(AH21<>"", INDEX($AJ$8:$AJ$1491, MATCH(AH21, $T$8:$T$1491, 0)),"") -> 0 | AG18: =IF(AH18<>"",AG17+1, "") -> 11 | AH18: NGÔ TRƯỜNG VŨ | AI18: 12A10 | AJ18: 0.147975
A19: =IF(B19<>"",A18+1,"") -> 15 | B19: LÊ NGỌC KHANH | C19: 10A1 | E19: Không phép | F19: 33000015 | R19: =IF(B19<>"", INDEX($V$8:$V$1491, MATCH(B19, $T$8:$T$1491, 0)),"") -> 3 | S19: =IF(T19<>"",S18+1,"") -> 12 | T19: =data!B16 -> NGUYỄN THỊ PHƯƠNG HẬU | U19: =data!C16 -> 10A1 | V19: 3 | Y19: ='10a1tr'!H13 -> 0 | Z19: ='10a1tr'!I13 -> 0 | AA19: ='10a1tr'!J13 -> 0 | AB19: ='10a1tr'!K13 -> 0 | AC19: ='10a1tr'!L13 -> 0 | AE19: =IF(B19<>"", INDEX($X$8:$X$1491, MATCH(B19, $T$8:$T$1491, 0)),"") -> 0 | AF19: =IF(AH22<>"", INDEX($AJ$8:$AJ$1491, MATCH(AH22, $T$8:$T$1491, 0)),"") -> 0 | AG19: =IF(AH19<>"",AG18+1, "") -> 12 | AH19: TRƯƠNG THẢO VY | AI19: 12A10 | AJ19: 0.149213
A20: =IF(B20<>"",A19+1,"") -> 16 | B20: NGUYỄN HOÀNG GIA KHÁNH | C20: 10A1 | E20: Không phép | F20: 33000016 | R20: =IF(B20<>"", INDEX($V$8:$V$1491, MATCH(B20, $T$8:$T$1491, 0)),"") -> 3 | S20: =IF(T20<>"",S19+1,"") -> 13 | T20: =data!B17 -> TRẦN VĨ HIỆP | U20: =data!C17 -> 10A1 | V20: 3 | Y20: ='10a1tr'!H14 -> 0 | Z20: ='10a1tr'!I14 -> 0 | AA20: ='10a1tr'!J14 -> 0 | AB20: ='10a1tr'!K14 -> 0 | AC20: ='10a1tr'!L14 -> 0 | AE20: =IF(B20<>"", INDEX($X$8:$X$1491, MATCH(B20, $T$8:$T$1491, 0)),"") -> 0 | AF20: =IF(AH23<>"", INDEX($AJ$8:$AJ$1491, MATCH(AH23, $T$8:$T$1491, 0)),"") -> 0 | AG20: =IF(AH20<>"",AG19+1, "") -> 13 | AH20: VÕ NGỌC PHƯƠNG VY | AI20: 12A10 | AJ20: 0.149225
A21: =IF(B21<>"",A20+1,"") -> 17 | B21: ĐỖ THỊ TRÚC LAM | C21: 10A1 | E21: Không phép | F21: 33000017 | R21: =IF(B21<>"", INDEX($V$8:$V$1491, MATCH(B21, $T$8:$T$1491, 0)),"") -> 3 | S21: =IF(T21<>"",S20+1,"") -> 14 | T21: =data!B18 -> VÕ LÊ GIA HUY | U21: =data!C18 -> 10A1 | V21: 3 | Y21: ='10a1tr'!H15 -> 0 | Z21: ='10a1tr'!I15 -> 0 | AA21: ='10a1tr'!J15 -> 0 | AB21: ='10a1tr'!K15 -> 0 | AC21: ='10a1tr'!L15 -> 0 | AE21: =IF(B21<>"", INDEX($X$8:$X$1491, MATCH(B21, $T$8:$T$1491, 0)),"") -> 0 | AF21: =IF(AH24<>"", INDEX($AJ$8:$AJ$1491, MATCH(AH24, $T$8:$T$1491, 0)),"") -> 0 | AG21: =IF(AH21<>"",AG20+1, "") -> 14 | AH21: TRẦN THỊ ÁNH XUÂN | AI21: 12A10 | AJ21: 0.150185
A22: =IF(B22<>"",A21+1,"") -> 18 | B22: LÝ NGỌC VÂN LAM | C22: 10A1 | E22: Không phép | F22: 33000018 | R22: =IF(B22<>"", INDEX($V$8:$V$1491, MATCH(B22, $T$8:$T$1491, 0)),"") -> 3 | S22: =IF(T22<>"",S21+1,"") -> 15 | T22: =data!B19 -> TỐNG THỊ NGỌC HUỲNH | U22: =data!C19 -> 10A1 | V22: 1 | Y22: ='10a1tr'!H16 -> 0 | Z22: ='10a1tr'!I16 -> 0 | AA22: ='10a1tr'!J16 -> 0 | AB22: ='10a1tr'!K16 -> 0 | AC22: ='10a1tr'!L16 -> 0 | AE22: =IF(B22<>"", INDEX($X$8:$X$1491, MATCH(B22, $T$8:$T$1491, 0)),"") -> 0 | AF22: =IF(AH25<>"", INDEX($AJ$8:$AJ$1491, MATCH(AH25, $T$8:$T$1491, 0)),"") -> 0 | AG22: =IF(AH22<>"",AG21+1, "") -> 15 | AH22: NGUYỄN NGỌC NHƯ Ý | AI22: 12A10 | AJ22: 0.150278
A23: =IF(B23<>"",A22+1,"") -> 19 | B23: LÊ MỸ LINH | C23: 10A1 | E23: Không phép | F23: 33000019 | R23: =IF(B23<>"", INDEX($V$8:$V$1491, MATCH(B23, $T$8:$T$1491, 0)),"") -> 3 | S23: =IF(T23<>"",S22+1,"") -> 16 | T23: =data!B20 -> LÊ NGỌC KHANH | U23: =data!C20 -> 10A1 | V23: 3 | Y23: ='10a1tr'!H17 -> 0 | Z23: ='10a1tr'!I17 -> 0 | AA23: ='10a1tr'!J17 -> 0 | AB23: ='10a1tr'!K17 -> 0 | AC23: ='10a1tr'!L17 -> 0 | AE23: =IF(B23<>"", INDEX($X$8:$X$1491, MATCH(B23, $T$8:$T$1491, 0)),"") -> 0 | AF23: =IF(AH26<>"", INDEX($AJ$8:$AJ$1491, MATCH(AH26, $T$8:$T$1491, 0)),"") -> 0 | AG23: =IF(AH23<>"",AG22+1, "") -> 16 | AH23: LƯU NGUYỄN NGỌC ÁI | AI23: 12A11 | AJ23: 0.150278
A24: =IF(B24<>"",A23+1,"") -> 20 | B24: PHẠM LÊ THANH NGÂN | C24: 10A1 | E24: Không phép | F24: 33000020 | R24: =IF(B24<>"", INDEX($V$8:$V$1491, MATCH(B24, $T$8:$T$1491, 0)),"") -> 3 | S24: =IF(T24<>"",S23+1,"") -> 17 | T24: =data!B21 -> NGUYỄN HOÀNG GIA KHÁNH | U24: =data!C21 -> 10A1 | V24: 3 | Y24: ='10a1tr'!H18 -> 0 | Z24: ='10a1tr'!I18 -> 0 | AA24: ='10a1tr'!J18 -> 0 | AB24: ='10a1tr'!K18 -> 0 | AC24: ='10a1tr'!L18 -> 0 | AE24: =IF(B24<>"", INDEX($X$8:$X$1491, MATCH(B24, $T$8:$T$1491, 0)),"") -> 0 | AF24: =IF(AH27<>"", INDEX($AJ$8:$AJ$1491, MATCH(AH27, $T$8:$T$1491, 0)),"") -> 0.152523 | AG24: =IF(AH24<>"",AG23+1, "") -> 17 | AH24: ĐÀM PHƯƠNG AN | AI24: 12A11 | AJ24: 0.150509
... A58: =IF(B58<>"",A57+1,"") -> 54 | B58: NGUYỄN NHẤT HUY | C58: 10A10 | E58: Không phép | F58: 33000055 | R58: =IF(B58<>"", INDEX($V$8:$V$1491, MATCH(B58, $T$8:$T$1491, 0)),"") -> 3 | S58: =IF(T58<>"",S57+1,"") -> 51 | T58: =data!B55 -> TRẦN GIA BẢO | U58: =data!C55 -> 10A10 | V58: 3 | Y58: ='10a1tr'!H52 -> 0 | Z58: ='10a1tr'!I52 -> 0 | AA58: ='10a1tr'!J52 -> 0 | AB58: ='10a1tr'!K52 -> 0 | AC58: ='10a1tr'!L52 -> 0 | AE58: =IF(B58<>"", INDEX($X$8:$X$1491, MATCH(B58, $T$8:$T$1491, 0)),"") -> 0 | AF58: =IF(AH61<>"", INDEX($AJ$8:$AJ$1491, MATCH(AH61, $T$8:$T$1491, 0)),"") -> 0 | AG58: =IF(AH58<>"",AG57+1, "") -> 51 | AH58: NGUYỄN NGỌC NHƯ Ý | AI58: 12A11 | AJ58: 0.152512
A59: =IF(B59<>"",A58+1,"") -> 55 | B59: HUỲNH LÂM QUỐC KHÁNH | C59: 10A10 | E59: Không phép | F59: 33000056 | R59: =IF(B59<>"", INDEX($V$8:$V$1491, MATCH(B59, $T$8:$T$1491, 0)),"") -> 3 | S59: =IF(T59<>"",S58+1,"") -> 52 | T59: =data!B56 -> NGUYỄN BẢO CHÂU | U59: =data!C56 -> 10A10 | V59: 3 | X59: 2 | Y59: ='10a1tr'!H53 -> 0 | Z59: ='10a1tr'!I53 -> 0 | AA59: ='10a1tr'!J53 -> 0 | AB59: ='10a1tr'!K53 -> 0 | AC59: ='10a1tr'!L53 -> 0 | AE59: =IF(B59<>"", INDEX($X$8:$X$1491, MATCH(B59, $T$8:$T$1491, 0)),"") -> 0 | AF59: =IF(AH62<>"", INDEX($AJ$8:$AJ$1491, MATCH(AH62, $T$8:$T$1491, 0)),"") -> 0 | AG59: =IF(AH59<>"",AG58+1, "") -> 52 | AH59: TRƯƠNG THỊ THUÝ AN | AI59: 12A2 | AJ59: 0.152523
A60: =IF(B60<>"",A59+1,"") -> 56 | B60: PHẠM TRẦN MINH KHÔI | C60: 10A10 | E60: Không phép | F60: 33000057 | R60: =IF(B60<>"", INDEX($V$8:$V$1491, MATCH(B60, $T$8:$T$1491, 0)),"") -> 3 | S60: =IF(T60<>"",S59+1,"") -> 53 | T60: =data!B57 -> HUỲNH CHÍ ĐẠO | U60: =data!C57 -> 10A10 | V60: 3 | Y60: ='10a1tr'!H54 -> 0 | Z60: ='10a1tr'!I54 -> 0 | AA60: ='10a1tr'!J54 -> 0 | AB60: ='10a1tr'!K54 -> 0 | AC60: ='10a1tr'!L54 -> 0 | AE60: =IF(B60<>"", INDEX($X$8:$X$1491, MATCH(B60, $T$8:$T$1491, 0)),"") -> 0 | AF60: =IF(AH63<>"", INDEX($AJ$8:$AJ$1491, MATCH(AH63, $T$8:$T$1491, 0)),"") -> 0 | AG60: =IF(AH60<>"",AG59+1, "") -> 53 | AH60: LÂM NHÃ ÂN | AI60: 12A2 | AJ60: 0.152523
A61: =IF(B61<>"",A60+1,"") -> 57 | B61: TRƯƠNG TRÍ KHÔI | C61: 10A10 | E61: Không phép | F61: 33000058 | R61: =IF(B61<>"", INDEX($V$8:$V$1491, MATCH(B61, $T$8:$T$1491, 0)),"") -> 3 | S61: =IF(T61<>"",S60+1,"") -> 54 | T61: =data!B58 -> NGUYỄN MAI SƠN GIANG | U61: =data!C58 -> 10A10 | V61: 3 | Y61: ='10a1tr'!H55 -> 0 | Z61: ='10a1tr'!I55 -> 0 | AA61: ='10a1tr'!J55 -> 0 | AB61: ='10a1tr'!K55 -> 0 | AC61: ='10a1tr'!L55 -> 0 | AE61: =IF(B61<>"", INDEX($X$8:$X$1491, MATCH(B61, $T$8:$T$1491, 0)),"") -> 0 | AF61: =IF(AH64<>"", INDEX($AJ$8:$AJ$1491, MATCH(AH64, $T$8:$T$1491, 0)),"") -> 0 | AG61: =IF(AH61<>"",AG60+1, "") -> 54 | AH61: LÊ CAO HOÀNG ANH | AI61: 12A2 | AJ61: 0.152546
A62: =IF(B62<>"",A61+1,"") -> 58 | B62: VÕ DUY KHÔI | C62: 10A10 | E62: Không phép | F62: 33000059 | R62: =IF(B62<>"", INDEX($V$8:$V$1491, MATCH(B62, $T$8:$T$1491, 0)),"") -> 3 | S62: =IF(T62<>"",S61+1,"") -> 55 | T62: =data!B59 -> ĐẶNG QUANG HOÀNG HIỆP | U62: =data!C59 -> 10A10 | V62: 3 | Y62: ='10a1tr'!H56 -> 0 | Z62: ='10a1tr'!I56 -> 0 | AA62: ='10a1tr'!J56 -> 0 | AB62: ='10a1tr'!K56 -> 0 | AC62: ='10a1tr'!L56 -> 0 | AE62: =IF(B62<>"", INDEX($X$8:$X$1491, MATCH(B62, $T$8:$T$1491, 0)),"") -> 0 | AF62: =IF(AH65<>"", INDEX($AJ$8:$AJ$1491, MATCH(AH65, $T$8:$T$1491, 0)),"") -> 0 | AG62: =IF(AH62<>"",AG61+1, "") -> 55 | AH62: TRẦN KỲ ANH | AI62: 12A2 | AJ62: 0.152546
A63: =IF(B63<>"",A62+1,"") -> 59 | B63: PHẠM THỊ CẨM LY | C63: 10A10 | E63: Không phép | F63: 33000060 | R63: =IF(B63<>"", INDEX($V$8:$V$1491, MATCH(B63, $T$8:$T$1491, 0)),"") -> 3 | S63: =IF(T63<>"",S62+1,"") -> 56 | T63: =data!B60 -> NGUYỄN NHẤT HUY | U63: =data!C60 -> 10A10 | V63: 3 | Y63: ='10a1tr'!H57 -> 0 | Z63: ='10a1tr'!I57 -> 0 | AA63: ='10a1tr'!J57 -> 0 | AB63: ='10a1tr'!K57 -> 0 | AC63: ='10a1tr'!L57 -> 0 | AE63: =IF(B63<>"", INDEX($X$8:$X$1491, MATCH(B63, $T$8:$T$1491, 0)),"") -> 0 | AF63: =IF(AH66<>"", INDEX($AJ$8:$AJ$1491, MATCH(AH66, $T$8:$T$1491, 0)),"") -> 0 | AG63: =IF(AH63<>"",AG62+1, "") -> 56 | AH63: VÕ LAN ANH | AI63: 12A2 | AJ63: 0.152558
A64: =IF(B64<>"",A63+1,"") -> 60 | B64: DANH THỊ NGỌC MAI | C64: 10A10 | E64: Không phép | F64: 33000061 | R64: =IF(B64<>"", INDEX($V$8:$V$1491, MATCH(B64, $T$8:$T$1491, 0)),"") -> 3 | S64: =IF(T64<>"",S63+1,"") -> 57 | T64: =data!B61 -> HUỲNH LÂM QUỐC KHÁNH | U64: =data!C61 -> 10A10 | V64: 3 | Y64: ='10a1tr'!H58 -> 0 | Z64: ='10a1tr'!I58 -> 0 | AA64: ='10a1tr'!J58 -> 0 | AB64: ='10a1tr'!K58 -> 0 | AC64: ='10a1tr'!L58 -> 0 | AE64: =IF(B64<>"", INDEX($X$8:$X$1491, MATCH(B64, $T$8:$T$1491, 0)),"") -> 0 | AF64: =IF(AH67<>"", INDEX($AJ$8:$AJ$1491, MATCH(AH67, $T$8:$T$1491, 0)),"") -> 0 | AG64: =IF(AH64<>"",AG63+1, "") -> 57 | AH64: DANH NGUYỄN VIẾT GIA BẢO | AI64: 12A2 | AJ64: 0.15257
A65: =IF(B65<>"",A64+1,"") -> 61 | B65: TĂNG LÊ NHỰT MINH | C65: 10A10 | E65: Không phép | F65: 33000062 | R65: =IF(B65<>"", INDEX($V$8:$V$1491, MATCH(B65, $T$8:$T$1491, 0)),"") -> 3 | S65: =IF(T65<>"",S64+1,"") -> 58 | T65: =data!B62 -> PHẠM TRẦN MINH KHÔI | U65: =data!C62 -> 10A10 | V65: 3 | Y65: ='10a1tr'!H59 -> 0 | Z65: ='10a1tr'!I59 -> 0 | AA65: ='10a1tr'!J59 -> 0 | AB65: ='10a1tr'!K59 -> 0 | AC65: ='10a1tr'!L59 -> 0 | AE65: =IF(B65<>"", INDEX($X$8:$X$1491, MATCH(B65, $T$8:$T$1491, 0)),"") -> 0 | AF65: =IF(AH68<>"", INDEX($AJ$8:$AJ$1491, MATCH(AH68, $T$8:$T$1491, 0)),"") -> 0 | AG65: =IF(AH65<>"",AG64+1, "") -> 58 | AH65: NGUYỄN LÊ BÌNH | AI65: 12A2 | AJ65: 0.152581
A66: =IF(B66<>"",A65+1,"") -> 62 | B66: NGUYỄN VÕ THÙY MUỘI | C66: 10A10 | E66: Không phép | F66: 33000063 | R66: =IF(B66<>"", INDEX($V$8:$V$1491, MATCH(B66, $T$8:$T$1491, 0)),"") -> 3 | S66: =IF(T66<>"",S65+1,"") -> 59 | T66: =data!B63 -> TRƯƠNG TRÍ KHÔI | U66: =data!C63 -> 10A10 | V66: 3 | Y66: ='10a1tr'!H60 -> 0 | Z66: ='10a1tr'!I60 -> 0 | AA66: ='10a1tr'!J60 -> 0 | AB66: ='10a1tr'!K60 -> 0 | AC66: ='10a1tr'!L60 -> 0 | AE66: =IF(B66<>"", INDEX($X$8:$X$1491, MATCH(B66, $T$8:$T$1491, 0)),"") -> 0 | AF66: =IF(AH69<>"", INDEX($AJ$8:$AJ$1491, MATCH(AH69, $T$8:$T$1491, 0)),"") -> 0 | AG66: =IF(AH66<>"",AG65+1, "") -> 59 | AH66: LÊ THỊ THU CÚC | AI66: 12A2 | AJ66: 0.152581
